Workbook

Sheet Phân việc
A1: BTL Quản lý thư viện – Bảng phân việc 5 người (MariaDB)
A2: C = phụ trách chính · R = review · H = hỗ trợ/góp ý. Ô vàng là ô cần cập nhật (Trạng thái, Ghi chú). Tên thật nhập ở sheet 'Thành viên'.
A4: Tổng hợp theo người
A5: Mã TV | B5: Họ tên | C5: Mảng | D5: Số việc chính (C) | E5: Đã hoàn thành | F5: % hoàn thành | G5: Số việc review (R)
A6: TV1 | B6: =IFERROR(INDEX('Thành viên'!$B$4:$B$8,MATCH(A6,'Thành viên'!$A$4:$A$8,0))&"","") | C6: Kho sách + trưởng nhóm | D6: =COUNTIF($K$14:$K$53,"C") -> 14 | E6: =COUNTIFS($K$14:$K$53,"C",$P$14:$P$53,"Hoàn thành") -> 0 | F6: =IF(D6=0,0,E6/D6) -> 0 | G6: =COUNTIF($K$14:$K$53,"R") -> 10
A7: TV2 | B7: =IFERROR(INDEX('Thành viên'!$B$4:$B$8,MATCH(A7,'Thành viên'!$A$4:$A$8,0))&"","") | C7: Con người, chi nhánh, dữ liệu | D7: =COUNTIF($L$14:$L$53,"C") -> 11 | E7: =COUNTIFS($L$14:$L$53,"C",$P$14:$P$53,"Hoàn thành") -> 0 | F7: =IF(D7=0,0,E7/D7) -> 0 | G7: =COUNTIF($L$14:$L$53,"R") -> 8
A8: TV3 | B8: =IFERROR(INDEX('Thành viên'!$B$4:$B$8,MATCH(A8,'Thành viên'!$A$4:$A$8,0))&"","") | C8: Mượn – trả – phạt | D8: =COUNTIF($M$14:$M$53,"C") -> 13 | E8: =COUNTIFS($M$14:$M$53,"C",$P$14:$P$53,"Hoàn thành") -> 0 | F8: =IF(D8=0,0,E8/D8) -> 0 | G8: =COUNTIF($M$14:$M$53,"R") -> 5
A9: TV4 | B9: =IFERROR(INDEX('Thành viên'!$B$4:$B$8,MATCH(A9,'Thành viên'!$A$4:$A$8,0))&"","") | C9: Phòng đọc + CSDL phân tán | D9: =COUNTIF($N$14:$N$53,"C") -> 15 | E9: =COUNTIFS($N$14:$N$53,"C",$P$14:$P$53,"Hoàn thành") -> 0 | F9: =IF(D9=0,0,E9/D9) -> 0 | G9: =COUNTIF($N$14:$N$53,"R") -> 4
A10: TV5 | B10: =IFERROR(INDEX('Thành viên'!$B$4:$B$8,MATCH(A10,'Thành viên'!$A$4:$A$8,0))&"","") | C10: Truy vấn, tối ưu, bảo mật, kiểm thử | D10: =COUNTIF($O$14:$O$53,"C") -> 14 | E10: =COUNTIFS($O$14:$O$53,"C",$P$14:$P$53,"Hoàn thành") -> 0 | F10: =IF(D10=0,0,E10/D10) -> 0 | G10: =COUNTIF($O$14:$O$53,"R") -> 10
A11: Toàn nhóm | C11: Tổng số đầu việc | D11: =COUNTA(A14:A53) -> 40 | E11: =COUNTIF(P14:P53,"Hoàn thành") -> 0 | F11: =IF(D11=0,0,E11/D11) -> 0
A13: Mã việc | B13: Giai đoạn | C13: Đầu việc | D13: Phụ trách | E13: Review | F13: Bắt đầu | G13: Hạn | H13: Sản phẩm / file | I13: Yêu cầu đề đáp ứng | J13: Phụ thuộc | K13: TV1 | L13: TV2 | M13: TV3 | N13: TV4 | O13: TV5 | P13: Trạng thái | Q13: Ghi chú
A14: NV01 | B14: 0. Chốt nền tảng | C14: Vẽ ERD khung (thực thể, liên kết, lực lượng) + soạn schema v0 + nhập thông số kịch bản | D14: TV1 | E14: Cả nhóm | F14: 46308 | G14: 46310 | H14: erd/ERD_khung.drawio; db/00_schema.sql (v0) | I14: Phần 2: thiết kế khái niệm, logic | J14: — | K14: C | L14: H | M14: H | N14: H | O14: H | P14: Chưa bắt đầu
A15: NV02 | B15: 0. Chốt nền tảng | C15: Góp ý schema v0 cho phần bảng thuộc mảng mình (comment trên repo) | D15: Cả nhóm | E15: TV1 | F15: 46310 | G15: 46313 | H15: Comment trên GitHub | I15: — | J15: NV01 | K15: R | L15: C | M15: C | N15: C | O15: C | P15: Chưa bắt đầu
A16: NV03 | B16: 0. Chốt nền tảng | C16: Quy ước procedure: tên, tham số p_, kết quả trả về, bảng mã lỗi SIGNAL | D16: TV5 | E16: TV1 | F16: 46308 | G16: 46314 | H16: docs/quy_uoc_procedure.md | I16: Thống nhất cài đặt | J16: — | K16: R | L16: H | M16: H | N16: H | O16: C | P16: Chưa bắt đầu
A17: NV04 | B17: 0. Chốt nền tảng | C17: Cuộc gọi 1 (45 phút): chốt góp ý, đóng băng schema v1 | D17: Cả nhóm | E17: — | F17: 46314 | G17: 46314 | H17: db/00_schema.sql (v1), CHANGELOG | I17: — | J17: NV02, NV03 | K17: C | L17: C | M17: C | N17: C | O17: C | P17: Chưa bắt đầu
A18: NV05 | B18: 1. Thiết kế | C18: ERD con Kho sách + ánh xạ quan hệ + PTH + khóa + BCNF | D18: TV1 | E18: TV3 | F18: 46310 | G18: 46321 | H18: erd/tv1_kho.drawio; baocao/tv1.docx (mục 3) | I18: ERD, ánh xạ, PTH, BCNF | J18: NV01 | K18: C | M18: R | P18: Chưa bắt đầu
A19: NV06 | B19: 1. Thiết kế | C19: ERD con Con người & chi nhánh + ánh xạ + PTH + khóa + BCNF | D19: TV2 | E19: TV4 | F19: 46310 | G19: 46321 | H19: erd/tv2_nguoi.drawio; baocao/tv2.docx | I19: ERD, ánh xạ, PTH, BCNF | J19: NV01 | L19: C | N19: R | P19: Chưa bắt đầu
A20: NV07 | B20: 1. Thiết kế | C20: ERD con Mượn – trả – phạt + ánh xạ + PTH + khóa + BCNF | D20: TV3 | E20: TV1 | F20: 46310 | G20: 46321 | H20: erd/tv3_muontra.drawio; baocao/tv3.docx | I20: ERD, ánh xạ, PTH, BCNF | J20: NV01 | K20: R | M20: C | P20: Chưa bắt đầu
A21: NV08 | B21: 1. Thiết kế | C21: ERD con Phòng đọc + ánh xạ + PTH + khóa + BCNF | D21: TV4 | E21: TV5 | F21: 46310 | G21: 46321 | H21: erd/tv4_phong.drawio; baocao/tv4.docx | I21: ERD, ánh xạ, PTH, BCNF | J21: NV01 | N21: C | O21: R | P21: Chưa bắt đầu
A22: NV09 | B22: 1. Thiết kế | C22: Ghép ERD tổng + tick checklist 'đủ mọi loại' thực thể/thuộc tính/liên kết | D22: TV1 | E22: Cả nhóm | F22: 46315 | G22: 46321 | H22: erd/ERD_tong.drawio | I22: Đủ mọi loại tập thực thể, thuộc tính, liên kết | J22: NV05–NV08 | K22: C | L22: R | M22: R | N22: R | O22: R | P22: Chưa bắt đầu
A23: NV10 | B23: 2. Cài đặt SQL | C23: DDL + CHECK/UNIQUE/FK có tên + function + procedure CRUD mảng Kho sách | D23: TV1 | E23: TV3 | F23: 46315 | G23: 46325 | H23: db/10_tv1_kho.sql | I23: Thêm/xóa/sửa/tìm kiếm; ràng buộc bằng SQL | J23: NV04 | K23: C | M23: R | P23: Chưa bắt đầu
A24: NV11 | B24: 2. Cài đặt SQL | C24: DDL + ràng buộc + function + procedure CRUD mảng Con người & chi nhánh | D24: TV2 | E24: TV4 | F24: 46315 | G24: 46325 | H24: db/20_tv2_nguoi.sql | I24: Thêm/xóa/sửa/tìm kiếm; ràng buộc bằng SQL | J24: NV04 | L24: C | N24: R | P24: Chưa bắt đầu
A25: NV12 | B25: 2. Cài đặt SQL | C25: DDL + ràng buộc + function tính phạt/đếm sách + procedure tra cứu mảng Mượn trả | D25: TV3 | E25: TV1 | F25: 46315 | G25: 46325 | H25: db/30_tv3_muontra.sql | I25: Ràng buộc bằng SQL | J25: NV04 | K25: R | M25: C | P25: Chưa bắt đầu
A26: NV13 | B26: 2. Cài đặt SQL | C26: DDL + ràng buộc + procedure CRUD mảng Phòng đọc | D26: TV4 | E26: TV5 | F26: 46315 | G26: 46325 | H26: db/40_tv4_phong.sql | I26: Thêm/xóa/sửa/tìm kiếm; ràng buộc bằng SQL | J26: NV04 | N26: C | O26: R | P26: Chưa bắt đầu
A27: NV14 | B27: 2. Cài đặt SQL | C27: Trigger TRG4, TRG5, TRG6 | D27: TV1 | E27: TV5 | F27: 46326 | G27: 46335 | H27: db/triggers/TRG4..6 | I27: ≥5 trigger; số lượng trên giá; tuổi thọ; giá cùng thể loại | J27: NV10, NV12 | K27: C | O27: R | P27: Chưa bắt đầu
A28: NV15 | B28: 2. Cài đặt SQL | C28: Transaction TX4 (nhập lô sách), TX5 (thanh lý sách hết hạn) | D28: TV1 | E28: TV5 | F28: 46326 | G28: 46335 | H28: db/tx/TX4, TX5 | I28: ≥5 transaction; sách hết hạn tách bảng riêng | J28: NV10 | K28: C | O28: R | P28: Chưa bắt đầu
A29: NV16 | B29: 2. Cài đặt SQL | C29: Trigger TRG8 + Transaction TX6 (đăng ký độc giả) | D29: TV2 | E29: TV5 | F29: 46326 | G29: 46335 | H29: db/triggers/TRG8; db/tx/TX6 | I29: ≥5 trigger/transaction | J29: NV11 | L29: C | O29: R | P29: Chưa bắt đầu
A30: NV17 | B30: 2. Cài đặt SQL | C30: Trigger TRG1, TRG2, TRG3 (10 cuốn/lần, 50 cuốn, tính phạt) | D30: TV3 | E30: TV5 | F30: 46326 | G30: 46335 | H30: db/triggers/TRG1..3 | I30: Giới hạn mượn; phí phạt trả muộn | J30: NV12 | M30: C | O30: R | P30: Chưa bắt đầu
A31: NV18 | B31: 2. Cài đặt SQL | C31: Transaction TX1 (mượn), TX2 (trả), TX3 (thanh toán phạt) | D31: TV3 | E31: TV5 | F31: 46326 | G31: 46335 | H31: db/tx/TX1..3 | I31: Mượn/trả 1–n cuốn; số lượng trên giá đổi | J31: NV12, NV10 | M31: C | O31: R | P31: Chưa bắt đầu
A32: NV19 | B32: 2. Cài đặt SQL | C32: Trigger TRG7 + Transaction TX7 (thuê phòng) | D32: TV4 | E32: TV5 | F32: 46326 | G32: 46335 | H32: db/triggers/TRG7; db/tx/TX7 | I32: Thuê phòng đọc theo lịch | J32: NV13 | N32: C | O32: R | P32: Chưa bắt đầu
A33: NV20 | B33: 2. Cài đặt SQL | C33: 6 truy vấn hiển thị bắt buộc (view/procedure) + biểu thức đại số quan hệ | D33: TV5 | E33: TV2 | F33: 46310 | G33: 46335 | H33: db/50_tv5_baocao.sql | I33: Toàn bộ 6 yêu cầu hiển thị của đề | J33: NV04 | L33: R | O33: C | P33: Chưa bắt đầu
A34: NV21 | B34: 2. Cài đặt SQL | C34: Tạo INDEX + so sánh EXPLAIN trước/sau cho 2 truy vấn | D34: TV5 | E34: TV2 | F34: 46329 | G34: 46339 | H34: db/50_tv5_baocao.sql; ảnh EXPLAIN | I34: Tối ưu truy vấn (nội dung môn học) | J34: NV20 | L34: R | O34: C | P34: Chưa bắt đầu
A35: NV22 | B35: 2. Cài đặt SQL | C35: Phân quyền: ROLE r_ThuThu, r_QuanLy; GRANT EXECUTE/SELECT tối thiểu | D35: TV5 | E35: TV2 | F35: 46329 | G35: 46339 | H35: db/60_tv5_baomat.sql | I35: An toàn bảo mật CSDL (bước 6) | J35: NV10–NV19 | L35: R | O35: C | P35: Chưa bắt đầu
A36: NV23 | B36: 3. Dữ liệu | C36: Seed danh mục: thể loại, 300 đầu sách, 1.500 cuốn, giá, phòng kho | D36: TV1 | E36: TV2 | F36: 46322 | G36: 46328 | H36: db/seed/01_tv1.sql | I36: Số sách phong phú | J36: NV10 | K36: C | L36: R | P36: Chưa bắt đầu
A37: NV24 | B37: 3. Dữ liệu | C37: Seed bảng phí phạt | D37: TV3 | E37: TV2 | F37: 46322 | G37: 46328 | H37: db/seed/03_tv3.sql | I37: Phí phạt theo thể loại | J37: NV12 | L37: R | M37: C | P37: Chưa bắt đầu
A38: NV25 | B38: 3. Dữ liệu | C38: Seed 21 phòng đọc + ~150 lượt thuê (gọi TX7) | D38: TV4 | E38: TV2 | F38: 46322 | G38: 46335 | H38: db/seed/04_tv4.sql | I38: Lịch thuê phòng | J38: NV19 | L38: R | N38: C | P38: Chưa bắt đầu
A39: NV26 | B39: 3. Dữ liệu | C39: Seed 3 chi nhánh, 15 thủ thư, 200 độc giả + sinh ~800 phiếu mượn/trả 3 tháng bằng TX1/TX2 + seed_all.sql | D39: TV2 | E39: TV3 | F39: 46322 | G39: 46337 | H39: db/seed/02_tv2.sql; db/seed/seed_all.sql | I39: Thư viện vận hành ≥3 tháng | J39: NV11, NV18 | L39: C | M39: R | P39: Chưa bắt đầu
A40: NV27 | B40: 4. Phân tán | C40: Số liệu giả định + phân mảnh ngang nguyên thủy (Pr, COM_MIN, minterm, PHORIZONTAL) | D40: TV4 | E40: TV1 | F40: 46310 | G40: 46328 | H40: phan_tan/phan_manh_ngang.xlsx; baocao/tv4.docx | I40: Phân mảnh (mục 5) | J40: NV01 | K40: R | N40: C | P40: Chưa bắt đầu
A41: NV28 | B41: 4. Phân tán | C41: Phân mảnh ngang dẫn xuất (bán kết nối) + phân mảnh dọc DOC_GIA bằng BEA | D41: TV4 | E41: TV1 | F41: 46322 | G41: 46335 | H41: phan_tan/BEA.xlsx; baocao/tv4.docx | I41: Phân mảnh (mục 5) | J41: NV27 | K41: R | N41: C | P41: Chưa bắt đầu
A42: NV29 | B42: 4. Phân tán | C42: Kiểm tra 3 quy tắc, cấp phát, nhân bản, sơ đồ tổng thể, minh họa 3 database QLTV_CN01..03 | D42: TV4 | E42: TV1 | F42: 46329 | G42: 46339 | H42: phan_tan/minh_hoa.sql; baocao/tv4.docx | I42: Định vị, nhân bản, sơ đồ tổng quát (mục 5) | J42: NV28, NV10–NV13 | K42: R | N42: C | P42: Chưa bắt đầu
...

Sheet TV1 - Kho sách
A1: TV1 – chi tiết công việc
A2: Kho sách: thể loại, đầu sách, tác giả, phòng kho, giá sách, cuốn sách, sách thanh lý · Trưởng nhóm
A3: Họ tên: | B3: =IFERROR(INDEX('Thành viên'!$B$4:$B$8,MATCH("TV1",'Thành viên'!$A$4:$A$8,0))&"","") | D3: Tiến độ: | E3: =IF(COUNTA(B6:B21)=0,0,COUNTIF(I6:I21,"Hoàn thành")/COUNTA(B6:B21)) -> 0
A5: STT | B5: Mã việc | C5: Nhóm việc | D5: Việc cụ thể | E5: Sản phẩm / file | F5: Tiêu chí xong | G5: Hạn | H5: Phụ trách | I5: Trạng thái | J5: Ghi chú
A6: 1 | B6: NV01 | C6: Chốt nền tảng | D6: Vẽ ERD khung: tất cả thực thể, liên kết, lực lượng (chưa cần thuộc tính chi tiết) | E6: erd/ERD_khung.drawio | F6: Cả nhóm nhìn thấy mảng mình nằm ở đâu | G6: 46310 | H6: TV1 | I6: Chưa bắt đầu
A7: 2 | B7: NV01 | C7: Chốt nền tảng | D7: Soạn schema v0: danh sách bảng, cột, kiểu, PK/FK, định dạng mã theo sheet 'Danh mục bảng' | E7: db/00_schema.sql | F7: Chạy được trên MariaDB trống | G7: 46310 | H7: TV1 | I7: Chưa bắt đầu
A8: 3 | B8: NV04 | C8: Chốt nền tảng | D8: Tổng hợp góp ý, chủ trì cuộc gọi 1, đóng băng schema v1, ghi CHANGELOG | E8: db/00_schema.sql v1 | F8: Tag v1 trên repo | G8: 46314 | H8: TV1 | I8: Chưa bắt đầu
A9: 4 | B9: NV05 | C9: Thiết kế | D9: ERD con: DAU_SACH (mạnh) – CUON_SACH (yếu, khóa bán phần STT), TAC_GIA đa trị → N:N, GIA_SACH – PHONG_KHO 1:N | E9: erd/tv1_kho.drawio | F9: Đúng ký hiệu Chen như slide | G9: 46317 | H9: TV1 | I9: Chưa bắt đầu
A10: 5 | B10: NV05 | C10: Thiết kế | D10: Ánh xạ ERD → quan hệ; liệt kê PTH từng bảng; tìm khóa bằng bao đóng; chứng minh BCNF | E10: baocao/tv1.docx | F10: Có F, khóa, kết luận BCNF cho mỗi bảng | G10: 46321 | H10: TV1 | I10: Chưa bắt đầu
A11: 6 | B11: NV09 | C11: Thiết kế | D11: Ghép ERD tổng từ 4 ERD con; tick sheet 'Checklist ERD' | E11: erd/ERD_tong.drawio | F11: Đủ 14 loại trong checklist | G11: 46321 | H11: TV1 | I11: Chưa bắt đầu
A12: 7 | B12: NV10 | C12: Cài đặt SQL | D12: MaDauSach dạng TR0012: CHECK (MaTheLoai = LEFT(MaDauSach,2)); MaCuonSach TR0012-003: CHECK (MaCuonSach = CONCAT(MaDauSach,'-',LPAD(STT,3,'0'))), UNIQUE(MaDauSach, STT) | E12: db/10_tv1_kho.sql | F12: Chèn mã sai định dạng bị từ chối | G12: 46325 | H12: TV1 | I12: Chưa bắt đầu
A13: 8 | B13: NV10 | C13: Cài đặt SQL | D13: CHECK: TuoiThoConLaiThang ≥ 0; TrangThai IN ('TrenGia','DangMuon','ChoThanhLy'); 0 ≤ SoLuongHienCo ≤ SucChua | E13: db/10_tv1_kho.sql | F13: Mỗi CHECK có 1 ca test bị chặn | G13: 46325 | H13: TV1 | I13: Chưa bắt đầu
A14: 9 | B14: NV10 | C14: Cài đặt SQL | D14: Procedure CRUD: sp_DauSach_Them/Sua/Xoa/TimKiem, sp_CuonSach_TimKiem, sp_GiaSach_*, sp_PhongKho_* | E14: db/10_tv1_kho.sql | F14: Đúng quy ước procedure (NV03) | G14: 46325 | H14: TV1 | I14: Chưa bắt đầu
A15: 10 | B15: NV14 | C15: Trigger | D15: TRG4: cập nhật số lượng trên giá + trạng thái cuốn khi mượn (AFTER INSERT CT_MUON) và khi trả (AFTER UPDATE MaPhieuTra) | E15: db/triggers/TRG4.sql | F15: Xem sheet 'Trigger & Transaction' | G15: 46335 | H15: TV1 | I15: Chưa bắt đầu
A16: 11 | B16: NV14 | C16: Trigger | D16: TRG5: giảm tuổi thọ 1 tháng mỗi lần mượn; về 0 → 'ChoThanhLy' | E16: db/triggers/TRG5.sql | F16: Xem sheet 'Trigger & Transaction' | G16: 46335 | H16: TV1 | I16: Chưa bắt đầu
A17: 12 | B17: NV14 | C17: Trigger | D17: TRG6: chặn xếp cuốn sách lên giá khác thể loại hoặc giá đã đầy | E17: db/triggers/TRG6.sql | F17: Xem sheet 'Trigger & Transaction' | G17: 46335 | H17: TV1 | I17: Chưa bắt đầu
... A21: 16 | B21: NV38 | C21: Báo cáo | D21: Viết mục 1 (phân tích yêu cầu); ghép báo cáo; mục lục tự động; nộp qua email | E21: baocao/BaoCao_tong.docx | F21: Nộp trước 20/11 | G21: 46346 | H21: TV1 | I21: Chưa bắt đầu

Sheet TV2 - Con người
A1: TV2 – chi tiết công việc
A2: Con người & chi nhánh: CHI_NHANH, NGUOI, SDT_NGUOI, DOC_GIA, THE_DOC_GIA, THU_THU · Dữ liệu 3 tháng
A3: Họ tên: | B3: =IFERROR(INDEX('Thành viên'!$B$4:$B$8,MATCH("TV2",'Thành viên'!$A$4:$A$8,0))&"","") | D3: Tiến độ: | E3: =IF(COUNTA(B6:B19)=0,0,COUNTIF(I6:I19,"Hoàn thành")/COUNTA(B6:B19)) -> 0
A5: STT | B5: Mã việc | C5: Nhóm việc | D5: Việc cụ thể | E5: Sản phẩm / file | F5: Tiêu chí xong | G5: Hạn | H5: Phụ trách | I5: Trạng thái | J5: Ghi chú
A6: 1 | B6: NV02 | C6: Chốt nền tảng | D6: Góp ý schema v0 phần bảng Con người & chi nhánh | E6: Comment repo | F6: Gửi trước 18/10 | G6: 46313 | H6: TV2 | I6: Chưa bắt đầu
A7: 2 | B7: NV06 | C7: Thiết kế | D7: ERD con: NGUOI ISA DOC_GIA/THU_THU (disjoint, toàn bộ); họ tên & địa chỉ là thuộc tính kép; SĐT đa trị; tuổi dẫn xuất | E7: erd/tv2_nguoi.drawio | F7: Đúng ký hiệu Chen | G7: 46317 | H7: TV2 | I7: Chưa bắt đầu
A8: 3 | B8: NV06 | C8: Thiết kế | D8: Liên kết 1:1 CHI_NHANH – thủ thư trưởng; liên kết đệ quy thủ thư quản lý thủ thư | E8: erd/tv2_nguoi.drawio | F8: Có cả 2 loại liên kết | G8: 46317 | H8: TV2 | I8: Chưa bắt đầu
A9: 4 | B9: NV06 | C9: Thiết kế | D9: Ánh xạ (ISA → bảng cha + con cùng PK; đa trị → SDT_NGUOI; đệ quy → MaQuanLy); PTH; khóa; BCNF | E9: baocao/tv2.docx | F9: Có F, khóa, BCNF | G9: 46321 | H9: TV2 | I9: Chưa bắt đầu
A10: 5 | B10: NV11 | C10: Cài đặt SQL | D10: CHI_NHANH.MaThuThuTruong FK + UNIQUE (thêm bằng ALTER TABLE sau khi có THU_THU, vì FK vòng) | E10: db/20_tv2_nguoi.sql | F10: Hai chi nhánh không chung thủ thư trưởng | G10: 46325 | H10: TV2 | I10: Chưa bắt đầu
A11: 6 | B11: NV11 | C11: Cài đặt SQL | D11: CHECK: LoaiNguoi IN ('DG','TT'); SoDienThoai REGEXP '^0[0-9]{9}$'; NgayHetHan > NgayCap; Email UNIQUE | E11: db/20_tv2_nguoi.sql | F11: Mỗi CHECK có ca bị chặn | G11: 46325 | H11: TV2 | I11: Chưa bắt đầu
A12: 7 | B12: NV11 | C12: Cài đặt SQL | D12: Function fn_Tuoi(p_NgaySinh); fn_TheConHan(p_MaDocGia, p_Ngay) | E12: db/20_tv2_nguoi.sql | F12: Dùng được trong TX1, TX7 | G12: 46325 | H12: TV2 | I12: Chưa bắt đầu
A13: 8 | B13: NV11 | C13: Cài đặt SQL | D13: Procedure CRUD: sp_DocGia_*, sp_ThuThu_*, sp_ChiNhanh_*, sp_DocGia_TimKiem (theo tên, SĐT, mã thẻ) | E13: db/20_tv2_nguoi.sql | F13: Đúng quy ước procedure | G13: 46325 | H13: TV2 | I13: Chưa bắt đầu
A14: 9 | B14: NV16 | C14: Trigger | D14: TRG8: chặn xóa độc giả còn giữ sách/còn nợ phạt; chặn sửa mã độc giả | E14: db/triggers/TRG8.sql | F14: Xem sheet 'Trigger & Transaction' | G14: 46335 | H14: TV2 | I14: Chưa bắt đầu
A15: 10 | B15: NV16 | C15: Transaction | D15: TX6 sp_DangKyDocGia: NGUOI + DOC_GIA + SĐT (JSON) + THE_DOC_GIA; sp_GiaHanThe | E15: db/tx/TX6.sql | F15: Lỗi giữa chừng → ROLLBACK | G15: 46335 | H15: TV2 | I15: Chưa bắt đầu
A16: 11 | B16: NV26 | C16: Dữ liệu | D16: Seed 3 chi nhánh, 15 thủ thư (có quan hệ quản lý), 200 độc giả, 1–3 SĐT mỗi người | E16: db/seed/02_tv2.sql | F16: Có độc giả thẻ hết hạn để test | G16: 46328 | H16: TV2 | I16: Chưa bắt đầu
A17: 12 | B17: NV26 | C17: Dữ liệu | D17: Sinh ~800 phiếu mượn/trả 01/07–30/09/2026 bằng vòng lặp gọi TX1/TX2 với ngày quá khứ; có ca quá hạn và độc giả giữ đúng 50 cuốn | E17: db/seed/02_tv2.sql | F17: Mọi trigger chạy thật, dữ liệu hợp lệ | G17: 46337 | H17: TV2 | I17: Chưa bắt đầu
... A19: 14 | B19: NV34 | C19: Báo cáo | D19: Viết phần Con người của mục 2, 3, 4 + mục minh chứng dữ liệu đã nạp | E19: baocao/tv2.docx | F19: Người review (TV4) đã đọc | G19: 46342 | H19: TV2 | I19: Chưa bắt đầu

Sheet TV3 - Mượn trả
A1: TV3 – chi tiết công việc
A2: Mượn – trả – phạt: PHIEU_MUON, CT_MUON, PHIEU_TRA, BANG_PHI_PHAT, PHIEU_PHAT
A3: Họ tên: | B3: =IFERROR(INDEX('Thành viên'!$B$4:$B$8,MATCH("TV3",'Thành viên'!$A$4:$A$8,0))&"","") | D3: Tiến độ: | E3: =IF(COUNTA(B6:B17)=0,0,COUNTIF(I6:I17,"Hoàn thành")/COUNTA(B6:B17)) -> 0
A5: STT | B5: Mã việc | C5: Nhóm việc | D5: Việc cụ thể | E5: Sản phẩm / file | F5: Tiêu chí xong | G5: Hạn | H5: Phụ trách | I5: Trạng thái | J5: Ghi chú
A6: 1 | B6: NV02 | C6: Chốt nền tảng | D6: Góp ý schema v0 phần bảng Mượn trả | E6: Comment repo | F6: Gửi trước 18/10 | G6: 46313 | H6: TV3 | I6: Chưa bắt đầu
A7: 2 | B7: NV07 | C7: Thiết kế | D7: ERD con: liên kết 3 ngôi THU_THU – DOC_GIA – CUON_SACH; CT_MUON là N:N có thuộc tính HanTra | E7: erd/tv3_muontra.drawio | F7: Đúng ký hiệu Chen | G7: 46317 | H7: TV3 | I7: Chưa bắt đầu
A8: 3 | B8: NV07 | C8: Thiết kế | D8: Ràng buộc (min,max): (1,10) cuốn mỗi phiếu; (0,50) cuốn đang giữ mỗi độc giả; MaPhieuTra NULL khi chưa trả | E8: erd/tv3_muontra.drawio | F8: Ghi trên đường nối | G8: 46317 | H8: TV3 | I8: Chưa bắt đầu
A9: 4 | B9: NV07 | C9: Thiết kế | D9: Ánh xạ; PTH; khóa; BCNF – tách PTH bắc cầu cuốn → thể loại → phí phạt ra BANG_PHI_PHAT; không lưu NgayTra trong CT_MUON | E9: baocao/tv3.docx | F9: Có F, khóa, BCNF | G9: 46321 | H9: TV3 | I9: Chưa bắt đầu
A10: 5 | B10: NV12 | C10: Cài đặt SQL | D10: CHECK: SoTien ≥ 0, SoNgayTre > 0; PK CT_MUON (MaPhieuMuon, MaCuonSach) | E10: db/30_tv3_muontra.sql | F10: Có ca bị chặn | G10: 46325 | H10: TV3 | I10: Chưa bắt đầu
A11: 6 | B11: NV12 | C11: Cài đặt SQL | D11: Function fn_SoSachDangMuon(p_MaDocGia); fn_HanTra(p_MaCuonSach, p_NgayMuon); fn_TinhTienPhat(p_MaCuonSach, p_HanTra, p_NgayTra) | E11: db/30_tv3_muontra.sql | F11: Kết quả khớp sheet 'Thông số kịch bản' | G11: 46325 | H11: TV3 | I11: Chưa bắt đầu
A12: 7 | B12: NV12 | C12: Cài đặt SQL | D12: Procedure tra cứu: sp_PhieuMuon_TimKiem, sp_LichSuMuon_DocGia, sp_PhieuPhat_ChuaThanhToan | E12: db/30_tv3_muontra.sql | F12: Đúng quy ước procedure | G12: 46325 | H12: TV3 | I12: Chưa bắt đầu
A13: 8 | B13: NV17 | C13: Trigger | D13: TRG1 tối đa 10 cuốn/lần; TRG2 tối đa 50 cuốn đang giữ; TRG3 lập phiếu phạt khi trả muộn | E13: db/triggers/TRG1..3.sql | F13: Xem sheet 'Trigger & Transaction' | G13: 46335 | H13: TV3 | I13: Chưa bắt đầu
A14: 9 | B14: NV18 | C14: Transaction | D14: TX1 sp_MuonSach (JSON danh sách cuốn, JSON_TABLE, SELECT … FOR UPDATE); TX2 sp_TraSach (1–n cuốn); TX3 sp_ThanhToanPhat | E14: db/tx/TX1..3.sql | F14: Kiểm tra cả luật khác bảng: hạn trả > ngày mượn, ngày trả ≥ ngày mượn | G14: 46335 | H14: TV3 | I14: Chưa bắt đầu
A15: 10 | B15: NV24 | C15: Dữ liệu | D15: Seed BANG_PHI_PHAT 6 thể loại; phối hợp TV2 sinh phiếu mượn/trả | E15: db/seed/03_tv3.sql | F15: Khớp sheet 'Thông số kịch bản' | G15: 46328 | H15: TV3 | I15: Chưa bắt đầu
A16: 11 | B16: NV34 | C16: Báo cáo | D16: Viết phần Mượn trả của mục 2, 3, 4 | E16: baocao/tv3.docx | F16: Người review (TV1) đã đọc | G16: 46342 | H16: TV3 | I16: Chưa bắt đầu
A17: 12 | B17: NV35 | C17: Báo cáo | D17: Mục ràng buộc số lượng bản ghi: liệt kê mọi giới hạn số lượng và cách cài (CHECK/trigger/procedure) | E17: baocao/tv3.docx | F17: Bao gồm 10, 50, 1–n, sức chứa giá, sức chứa phòng | G17: 46342 | H17: TV3 | I17: Chưa bắt đầu

Sheet TV4 - Phòng đọc & Phân tán
A1: TV4 – chi tiết công việc
A2: Phòng đọc: PHONG_DOC, BANG_GIA_PHONG, PHIEU_THUE_PHONG · Toàn bộ mục 5 CSDL phân tán
A3: Họ tên: | B3: =IFERROR(INDEX('Thành viên'!$B$4:$B$8,MATCH("TV4",'Thành viên'!$A$4:$A$8,0))&"","") | D3: Tiến độ: | E3: =IF(COUNTA(B6:B21)=0,0,COUNTIF(I6:I21,"Hoàn thành")/COUNTA(B6:B21)) -> 0
A5: STT | B5: Mã việc | C5: Nhóm việc | D5: Việc cụ thể | E5: Sản phẩm / file | F5: Tiêu chí xong | G5: Hạn | H5: Phụ trách | I5: Trạng thái | J5: Ghi chú
A6: 1 | B6: NV02 | C6: Chốt nền tảng | D6: Góp ý schema v0 phần bảng Phòng đọc | E6: Comment repo | F6: Gửi trước 18/10 | G6: 46313 | H6: TV4 | I6: Chưa bắt đầu
A7: 2 | B7: NV08 | C7: Thiết kế | D7: ERD con: phiếu thuê (DOC_GIA – PHONG_DOC) được THU_THU duyệt → mô hình kết hợp (aggregation) | E7: erd/tv4_phong.drawio | F7: Đúng ký hiệu Chen | G7: 46317 | H7: TV4 | I7: Chưa bắt đầu
A8: 3 | B8: NV08 | C8: Thiết kế | D8: Ánh xạ; PTH; khóa; BCNF | E8: baocao/tv4.docx | F8: Có F, khóa, BCNF | G8: 46321 | H8: TV4 | I8: Chưa bắt đầu
A9: 4 | B9: NV13 | C9: Cài đặt SQL | D9: CHECK: KetThuc > BatDau; TIME(BatDau) ≥ '07:00'; TIME(KetThuc) ≤ '21:00'; MINUTE(BatDau)=0 (giờ tròn); SucChua > 0 | E9: db/40_tv4_phong.sql | F9: Có ca bị chặn | G9: 46325 | H9: TV4 | I9: Chưa bắt đầu
A10: 5 | B10: NV13 | C10: Cài đặt SQL | D10: Procedure CRUD: sp_PhongDoc_*, sp_PhongDoc_TimKiem (chi nhánh, loại, sức chứa) | E10: db/40_tv4_phong.sql | F10: Đúng quy ước procedure | G10: 46325 | H10: TV4 | I10: Chưa bắt đầu
A11: 6 | B11: NV19 | C11: Trigger | D11: TRG7: chặn đặt phòng trùng khung giờ | E11: db/triggers/TRG7.sql | F11: Xem sheet 'Trigger & Transaction' | G11: 46335 | H11: TV4 | I11: Chưa bắt đầu
A12: 7 | B12: NV19 | C12: Transaction | D12: TX7 sp_ThuePhong: kiểm tra thẻ, nợ phạt, sức chứa, đặt trước ≤ 14 ngày, tính tiền | E12: db/tx/TX7.sql | F12: Xem sheet 'Trigger & Transaction' | G12: 46335 | H12: TV4 | I12: Chưa bắt đầu
A13: 8 | B13: NV25 | C13: Dữ liệu | D13: Seed 21 phòng (mỗi chi nhánh 5 nhóm + 2 hội thảo) + ~150 lượt thuê gọi TX7 | E13: db/seed/04_tv4.sql | F13: Có thời điểm phòng trống/đang dùng để test truy vấn 6 | G13: 46335 | H13: TV4 | I13: Chưa bắt đầu
A14: 9 | B14: NV27 | C14: Phân tán | D14: Bảng số liệu giả định: số bản ghi mỗi bảng, ứng dụng q1..qn, tần suất acc tại 3 site | E14: phan_tan/so_lieu.xlsx | F14: Đủ để tính COM_MIN, AA | G14: 46321 | H14: TV4 | I14: Chưa bắt đầu
A15: 10 | B15: NV27 | C15: Phân tán | D15: Phân mảnh ngang nguyên thủy CUON_SACH, DOC_GIA, PHONG_DOC: Pr → COM_MIN → minterm → phép kéo theo → PHORIZONTAL | E15: baocao/tv4.docx | F15: Trình bày đúng các bước slide 7b | G15: 46328 | H15: TV4 | I15: Chưa bắt đầu
A16: 11 | B16: NV28 | C16: Phân tán | D16: Phân mảnh ngang dẫn xuất PHIEU_MUON, CT_MUON bằng bán kết nối | E16: baocao/tv4.docx | F16: Có biểu thức ⋉ cho từng mảnh | G16: 46332 | H16: TV4 | I16: Chưa bắt đầu
A17: 12 | B17: NV28 | C17: Phân tán | D17: Phân mảnh dọc DOC_GIA: ma trận A → AA → BEA (cont) → CA → chọn điểm chia max z = CTQ·CBQ − COQ² | E17: phan_tan/BEA.xlsx | F17: Làm như ví dụ PROJ slide 7c | G17: 46335 | H17: TV4 | I17: Chưa bắt đầu
... A21: 16 | B21: NV36 | C21: Báo cáo | D21: Viết mục 5 hoàn chỉnh | E21: baocao/tv4.docx | F21: TV1 đã đọc | G21: 46342 | H21: TV4 | I21: Chưa bắt đầu

Sheet TV5 - Truy vấn & Kiểm thử
A1: TV5 – chi tiết công việc
A2: Truy vấn báo cáo, tối ưu, bảo mật, kiểm thử tích hợp, giao diện tối giản
A3: Họ tên: | B3: =IFERROR(INDEX('Thành viên'!$B$4:$B$8,MATCH("TV5",'Thành viên'!$A$4:$A$8,0))&"","") | D3: Tiến độ: | E3: =IF(COUNTA(B6:B15)=0,0,COUNTIF(I6:I15,"Hoàn thành")/COUNTA(B6:B15)) -> 0
A5: STT | B5: Mã việc | C5: Nhóm việc | D5: Việc cụ thể | E5: Sản phẩm / file | F5: Tiêu chí xong | G5: Hạn | H5: Phụ trách | I5: Trạng thái | J5: Ghi chú
A6: 1 | B6: NV03 | C6: Chốt nền tảng | D6: Viết quy ước procedure: tên sp_<Doi tuong>_<Viec>, tham số p_, procedure tìm kiếm trả SELECT, procedure thêm trả mã mới (OUT), bảng mã lỗi E1xx–E4xx dùng với SIGNAL | E6: docs/quy_uoc_procedure.md | F6: Chốt cùng schema 19/10 | G6: 46314 | H6: TV5 | I6: Chưa bắt đầu
A7: 2 | B7: NV20 | C7: Truy vấn | D7: Viết nháp 6 truy vấn theo schema v0 (chưa cần dữ liệu thật) | E7: db/50_tv5_baocao.sql | F7: Chạy được trên DB trống | G7: 46321 | H7: TV5 | I7: Chưa bắt đầu
A8: 3 | B8: NV20 | C8: Truy vấn | D8: Hoàn thiện 6 view/procedure theo sheet 'Truy vấn báo cáo' + biểu thức đại số quan hệ cho mỗi truy vấn | E8: db/50_tv5_baocao.sql | F8: Kết quả đúng thứ tự sắp xếp đề yêu cầu | G8: 46335 | H8: TV5 | I8: Chưa bắt đầu
A9: 4 | B9: NV21 | C9: Tối ưu | D9: Tạo INDEX cho HanTra, MaPhieuTra, MaDocGia, MaCuonSach, (MaPhongDoc, BatDau); so sánh EXPLAIN trước/sau cho 2 truy vấn | E9: db/50_tv5_baocao.sql | F9: Có ảnh EXPLAIN trước/sau | G9: 46339 | H9: TV5 | I9: Chưa bắt đầu
A10: 5 | B10: NV22 | C10: Bảo mật | D10: CREATE ROLE r_ThuThu, r_QuanLy; GRANT EXECUTE trên procedure, SELECT trên view; không cấp quyền trực tiếp trên bảng; tạo 2 user mẫu | E10: db/60_tv5_baomat.sql | F10: User thủ thư không SELECT được bảng gốc | G10: 46339 | H10: TV5 | I10: Chưa bắt đầu
A11: 6 | B11: NV30 | C11: Kiểm thử | D11: Script test cho 8 trigger + 7 transaction: 1 ca hợp lệ + 1 ca bị chặn, ghi kết quả mong đợi | E11: db/tests/*.sql | F11: 15 file test chạy đúng | G11: 46339 | H11: TV5 | I11: Chưa bắt đầu
A12: 7 | B12: NV30 | C12: Kiểm thử | D12: Minh chứng số bản ghi mỗi bảng (information_schema.TABLES + SELECT COUNT(*)) | E12: db/tests/dem_ban_ghi.sql | F12: Đưa ảnh vào báo cáo | G12: 46339 | H12: TV5 | I12: Chưa bắt đầu
A13: 8 | B13: NV31 | C13: Tích hợp | D13: Mỗi cuối tuần: DROP DATABASE, chạy build_all.sql + seed_all.sql, dán lỗi vào nhóm | E13: Tin nhắn nhóm | F13: Từ 25/10 đến 16/11 | G13: 46342 | H13: TV5 | I13: Chưa bắt đầu
A14: 9 | B14: NV33 | C14: Giao diện | D14: Giao diện tối giản gọi procedure/view: CRUD 4 mảng, mượn/trả, thuê phòng, 6 màn hình thống kê; không chứa luật nghiệp vụ | E14: app/ | F14: Hiện đúng thông báo lỗi từ SIGNAL | G14: 46342 | H14: TV5 | I14: Chưa bắt đầu
A15: 10 | B15: NV34 | C15: Báo cáo | D15: Viết phần truy vấn, tối ưu, bảo mật, giao diện của mục 4 | E15: baocao/tv5.docx | F15: Người review (TV2) đã đọc | G15: 46342 | H15: TV5 | I15: Chưa bắt đầu

Sheet Trigger & Transaction
A1: Đặc tả 8 trigger và 7 transaction (cú pháp MariaDB)
A2: Trigger chặn vi phạm bằng SIGNAL SQLSTATE '45000' SET MESSAGE_TEXT = '<Mã lỗi>: …'. MariaDB không cho trigger sửa chính bảng đã kích hoạt nó (lỗi 1442).
A4: Mã | B4: Loại | C4: Tên đối tượng | D4: Bảng · sự kiện | E4: Luật nghiệp vụ (đề) | F4: Xử lý | G4: Mã lỗi | H4: Người làm | I4: Ca test hợp lệ | J4: Ca test bị chặn | K4: Trạng thái
A5: TRG1 | B5: Trigger | C5: trg_CTMuon_ToiDa10 | D5: CT_MUON · BEFORE INSERT | E5: Mỗi phiếu mượn tối đa 10 cuốn | F5: Đếm CT_MUON cùng MaPhieuMuon; ≥ 10 → SIGNAL | G5: E101 | H5: TV3 | I5: Phiếu có 9 cuốn, thêm cuốn thứ 10 → OK | J5: Thêm cuốn thứ 11 → bị chặn E101 | K5: Chưa bắt đầu
A6: TRG2 | B6: Trigger | C6: trg_CTMuon_ToiDa50 | D6: CT_MUON · BEFORE INSERT | E6: Một độc giả giữ tối đa 50 cuốn chưa trả | F6: fn_SoSachDangMuon(độc giả của phiếu) ≥ 50 → SIGNAL | G6: E102 | H6: TV3 | I6: Độc giả đang giữ 49 → mượn thêm 1 OK | J6: Đang giữ 50 → mượn thêm bị chặn E102 | K6: Chưa bắt đầu
A7: TRG3 | B7: Trigger | C7: trg_CTMuon_LapPhieuPhat | D7: CT_MUON · AFTER UPDATE (MaPhieuTra NULL → có giá trị) | E7: Trả muộn bị phạt theo thể loại | F7: Nếu ngày trả (PHIEU_TRA) > HanTra → INSERT PHIEU_PHAT với fn_TinhTienPhat | G7: — | H7: TV3 | I7: Truyện trễ 3 ngày → phạt 130.000đ | J7: Trả đúng hạn → không có phiếu phạt | K7: Chưa bắt đầu
A8: TRG4 | B8: Trigger | C8: trg_CTMuon_GiamTrenGia / trg_CTMuon_TangTrenGia | D8: CT_MUON · AFTER INSERT và AFTER UPDATE | E8: Mượn thì số sách trên giá giảm, trả thì tăng | F8: Cập nhật GIA_SACH.SoLuongHienCo ±1 và CUON_SACH.TrangThai | G8: — | H8: TV1 | I8: Mượn 3 cuốn cùng giá → giảm 3 | J8: Mượn cuốn đang 'DangMuon' → bị chặn E104 (kiểm ở TX1) | K8: Chưa bắt đầu
A9: TRG5 | B9: Trigger | C9: trg_CTMuon_GiamTuoiTho | D9: CT_MUON · AFTER INSERT (FOLLOWS TRG4) | E9: Mỗi lần mượn tuổi thọ giảm 1 tháng | F9: UPDATE CUON_SACH SET TuoiThoConLaiThang = TuoiThoConLaiThang − 1; về 0 → TrangThai 'ChoThanhLy' | G9: — | H9: TV1 | I9: Cuốn còn 5 tháng → còn 4 | J9: Cuốn còn 1 tháng → về 0, chuyển 'ChoThanhLy' | K9: Chưa bắt đầu
A10: TRG6 | B10: Trigger | C10: trg_CuonSach_DungGia | D10: CUON_SACH · BEFORE INSERT / BEFORE UPDATE (MaGia) | E10: Mỗi giá chỉ chứa sách cùng thể loại, không vượt sức chứa | F10: GIA_SACH.MaTheLoai ≠ LEFT(NEW.MaDauSach,2) hoặc giá đầy → SIGNAL | G10: E301 | H10: TV1 | I10: Xếp cuốn TR lên giá TR → OK | J10: Xếp cuốn TK lên giá TR → bị chặn E301 | K10: Chưa bắt đầu
A11: TRG7 | B11: Trigger | C11: trg_ThuePhong_KhongTrung | D11: PHIEU_THUE_PHONG · BEFORE INSERT / BEFORE UPDATE | E11: Một phòng không có 2 lượt thuê trùng giờ | F11: EXISTS lượt cùng phòng, chưa hủy, BatDau < NEW.KetThuc AND KetThuc > NEW.BatDau → SIGNAL | G11: E201 | H11: TV4 | I11: Thuê 9–11h khi đã có 7–9h → OK | J11: Thuê 8–10h khi đã có 7–9h → bị chặn E201 | K11: Chưa bắt đầu
A12: TRG8 | B12: Trigger | C12: trg_DocGia_ChanXoa / trg_DocGia_ChanSuaMa | D12: DOC_GIA · BEFORE DELETE và BEFORE UPDATE | E12: Không xóa độc giả còn giữ sách/còn nợ phạt; không sửa mã | F12: Còn CT_MUON chưa trả hoặc PHIEU_PHAT chưa thanh toán → SIGNAL; NEW.MaNguoi <> OLD.MaNguoi → SIGNAL | G12: E401, E402 | H12: TV2 | I12: Xóa độc giả đã trả hết, không nợ → OK | J12: Xóa độc giả đang giữ 2 cuốn → bị chặn E401 | K12: Chưa bắt đầu
A13: TX1 | B13: Transaction | C13: sp_MuonSach(p_MaDocGia, p_MaThuThu, p_DsCuon JSON, p_NgayMuon) | D13: PHIEU_MUON, CT_MUON (+ TRG1, 2, 4, 5) | E13: Mượn 1–10 cuốn trong một lần | F13: Kiểm thẻ còn hạn (E103) → SELECT … FOR UPDATE các cuốn, phải 'TrenGia' (E104) → tạo phiếu → INSERT CT_MUON với HanTra = fn_HanTra → COMMIT; lỗi → ROLLBACK cả phiếu | G13: E103, E104 | H13: TV3 | I13: Mượn 3 cuốn hợp lệ → 1 phiếu, 3 dòng chi tiết | J13: 1 trong 3 cuốn đang được mượn → không tạo gì cả | K13: Chưa bắt đầu
A14: TX2 | B14: Transaction | C14: sp_TraSach(p_MaDocGia, p_MaThuThu, p_DsCuon JSON, p_NgayTra) | D14: PHIEU_TRA, CT_MUON (+ TRG3, 4) | E14: Trả 1 đến nhiều cuốn | F14: Tạo PHIEU_TRA → UPDATE CT_MUON SET MaPhieuTra → trả về tổng tiền phạt; ngày trả < ngày mượn → SIGNAL | G14: E105 | H14: TV3 | I14: Trả 2 cuốn, 1 trễ → 1 phiếu phạt | J14: Trả cuốn độc giả không mượn → ROLLBACK | K14: Chưa bắt đầu
A15: TX3 | B15: Transaction | C15: sp_ThanhToanPhat(p_MaDocGia, p_MaThuThu) | D15: PHIEU_PHAT | E15: Thanh toán toàn bộ phạt chưa trả | F15: UPDATE DaThanhToan = 1, NgayThanhToan; trả về tổng tiền | G15: — | H15: TV3 | I15: Độc giả nợ 2 phiếu → cả 2 đã thanh toán | J15: Không có phiếu nợ → báo E106 | K15: Chưa bắt đầu
... A19: TX7 | B19: Transaction | C19: sp_ThuePhong(p_MaDocGia, p_MaPhongDoc, p_MaThuThu, p_BatDau, p_KetThuc, p_SoNguoi) | D19: PHIEU_THUE_PHONG (+ TRG7) | E19: Thuê phòng học nhóm/hội thảo | F19: Kiểm thẻ (E103), nợ phạt (E107), sức chứa (E202), số giờ theo loại phòng, đặt trước ≤ 14 ngày → INSERT với TongTien = số giờ × giá | G19: E103, E107, E202 | H19: TV4 | I19: Nhóm 6 người thuê phòng 10 chỗ 2 giờ → 100.000đ | J19: 12 người thuê phòng 10 chỗ → bị chặn E202 | K19: Chưa bắt đầu

Sheet Truy vấn báo cáo
A1: 6 truy vấn hiển thị bắt buộc của đề (TV5)
A2: Mỗi truy vấn kèm biểu thức đại số quan hệ trong báo cáo. Ngày tham chiếu 'hôm nay' dùng tham số p_Ngay để demo được với dữ liệu quá khứ.
A4: STT | B4: Yêu cầu của đề | C4: Tên đối tượng | D4: Bảng dùng | E4: Kỹ thuật SQL | F4: Sắp xếp | G4: Biểu thức ĐSQH (điền) | H4: Trạng thái
A5: 1 | B5: Sách đã được mượn (chưa trả), sắp theo thời hạn trả | C5: v_SachDangMuon | D5: CT_MUON, PHIEU_MUON, CUON_SACH, DAU_SACH, DOC_GIA/NGUOI | E5: WHERE MaPhieuTra IS NULL; JOIN 5 bảng | F5: HanTra ASC | H5: Chưa bắt đầu
A6: 2 | B6: Sách quá hạn trả, sắp theo số ngày quá hạn | C6: sp_SachQuaHan(p_Ngay) | D6: CT_MUON, PHIEU_MUON, CUON_SACH, DAU_SACH | E6: DATEDIFF(p_Ngay, HanTra) > 0 AND MaPhieuTra IS NULL | F6: Số ngày quá hạn DESC | H6: Chưa bắt đầu
A7: 3 | B7: Đầu sách theo lượt mượn nhiều nhất | C7: v_DauSachTheoLuotMuon | D7: DAU_SACH, CUON_SACH, CT_MUON | E7: LEFT JOIN + GROUP BY MaDauSach + COUNT | F7: Lượt mượn DESC | H7: Chưa bắt đầu
A8: 4 | B8: Độc giả có sách trả muộn, theo tổng tiền phạt rồi số sách trả muộn | C8: v_DocGiaTraMuon | D8: PHIEU_PHAT, CT_MUON, PHIEU_MUON, DOC_GIA/NGUOI | E8: GROUP BY độc giả; SUM(SoTien), COUNT(*) | F8: Tổng phạt DESC, số sách trễ DESC | H8: Chưa bắt đầu
A9: 5 | B9: Sách sắp hết hạn sử dụng (còn dưới 2 năm) | C9: v_SachSapHetHan | D9: CUON_SACH, DAU_SACH, THE_LOAI | E9: WHERE TuoiThoConLaiThang < 24 | F9: Tuổi thọ còn lại ASC | H9: Chưa bắt đầu
A10: 6 | B10: Phòng đọc đã có / chưa có người sử dụng tại một thời điểm | C10: sp_PhongTaiThoiDiem(p_ThoiDiem) | D10: PHONG_DOC, PHIEU_THUE_PHONG | E10: LEFT JOIN … ON BatDau ≤ p_ThoiDiem < KetThuc; CASE → 'Đang dùng'/'Trống' | F10: Chi nhánh, trạng thái | H10: Chưa bắt đầu

Sheet Danh mục bảng
A1: Danh mục 23 bảng – hợp đồng dữ liệu (schema v0 do TV1 soạn)
A2: Đây là gợi ý ban đầu; bản chốt là db/00_schema.sql v1 sau cuộc gọi 19/10.
A4: Bảng | B4: Mảng | C4: Chủ | D4: Khóa chính | E4: Khóa ngoại | F4: Thuộc tính chính | G4: CHECK / UNIQUE | H4: Vai trò trong ERD
A5: THE_LOAI | B5: Kho sách | C5: TV1 | D5: MaTheLoai | E5: — | F5: TenTheLoai, SoNgayMuon, TuoiThoNam | G5: SoNgayMuon > 0, TuoiThoNam > 0 | H5: Thực thể mạnh
A6: DAU_SACH | B6: Kho sách | C6: TV1 | D6: MaDauSach (TR0012) | E6: MaTheLoai → THE_LOAI | F6: TenSach, NhaXuatBan, NamXuatBan, SoNgayMuonRieng (NULL) | G6: MaTheLoai = LEFT(MaDauSach,2) | H6: Thực thể mạnh, sở hữu CUON_SACH
A7: TAC_GIA | B7: Kho sách | C7: TV1 | D7: MaTacGia | E7: — | F7: TenTacGia, QuocTich | G7: — | H7: Thực thể mạnh
A8: DAU_SACH_TAC_GIA | B8: Kho sách | C8: TV1 | D8: (MaDauSach, MaTacGia) | E8: → DAU_SACH, → TAC_GIA | F8: — | G8: — | H8: N:N (từ thuộc tính đa trị tác giả)
A9: PHONG_KHO | B9: Kho sách | C9: TV1 | D9: MaPhongKho | E9: MaChiNhanh → CHI_NHANH | F9: TenPhong, Tang | G9: — | H9: Phòng đựng sách
A10: GIA_SACH | B10: Kho sách | C10: TV1 | D10: MaGia | E10: MaPhongKho → PHONG_KHO; MaTheLoai → THE_LOAI | F10: SucChua, SoLuongHienCo | G10: 0 ≤ SoLuongHienCo ≤ SucChua | H10: 1:N với PHONG_KHO
A11: CUON_SACH | B11: Kho sách | C11: TV1 | D11: MaCuonSach (TR0012-003) | E11: MaDauSach → DAU_SACH; MaGia → GIA_SACH | F11: STT, NgayNhap, TuoiThoConLaiThang, TrangThai | G11: MaCuonSach = CONCAT(MaDauSach,'-',LPAD(STT,3,'0')); UNIQUE(MaDauSach,STT); TrangThai IN (…) | H11: Thực thể yếu (khóa bán phần STT)
A12: SACH_THANH_LY | B12: Kho sách | C12: TV1 | D12: MaCuonSach | E12: MaDauSach → DAU_SACH | F12: STT, NgayNhap, NgayThanhLy, LyDo | G12: — | H12: Danh mục sách hết niên hạn
A13: CHI_NHANH | B13: Con người | C13: TV2 | D13: MaChiNhanh | E13: MaThuThuTruong → THU_THU (UNIQUE, ALTER sau) | F13: TenChiNhanh, DiaChi, GioMo, GioDong | G13: GioMo < GioDong | H13: 1:1 với thủ thư trưởng
A14: NGUOI | B14: Con người | C14: TV2 | D14: MaNguoi | E14: — | F14: Ho, Dem, Ten, NgaySinh, GioiTinh, SoNha, Phuong, Quan, TinhTP, Email, LoaiNguoi | G14: LoaiNguoi IN ('DG','TT'); Email UNIQUE | H14: Lớp cha ISA; thuộc tính kép
A15: SDT_NGUOI | B15: Con người | C15: TV2 | D15: (MaNguoi, SoDienThoai) | E15: MaNguoi → NGUOI | F15: — | G15: SoDienThoai REGEXP '^0[0-9]{9}$' | H15: Thuộc tính đa trị
... A27: — (view/index/role) | B27: Báo cáo | C27: TV5 | D27: — | E27: — | F27: 6 view/procedure báo cáo, index, role | G27: — | H27: Không tạo bảng

Sheet Checklist ERD
A1: Checklist 'đủ mọi loại' thực thể, thuộc tính, liên kết
A2: TV1 tick khi ghép ERD tổng (NV09).
A4: Loại (chương 3) | B4: Ví dụ trong kịch bản | C4: Mảng | D4: Đã có trong ERD tổng?
A5: Tập thực thể mạnh | B5: DAU_SACH, DOC_GIA, PHONG_DOC | C5: Tất cả | D5: Chưa bắt đầu
A6: Tập thực thể yếu | B6: CUON_SACH phụ thuộc DAU_SACH (khóa bán phần STT) | C6: TV1 | D6: Chưa bắt đầu
A7: Thuộc tính kép | B7: Họ tên (họ, đệm, tên); địa chỉ (số nhà, phường, quận, tỉnh) | C7: TV2 | D7: Chưa bắt đầu
A8: Thuộc tính đa trị | B8: SĐT của người; tác giả của đầu sách | C8: TV2, TV1 | D8: Chưa bắt đầu
A9: Thuộc tính dẫn xuất | B9: Tuổi; số ngày quá hạn; tiền phạt; tuổi thọ còn lại | C9: TV2, TV3, TV1 | D9: Chưa bắt đầu
A10: Thuộc tính rỗng | B10: CT_MUON.MaPhieuTra (NULL khi chưa trả); DAU_SACH.SoNgayMuonRieng | C10: TV3, TV1 | D10: Chưa bắt đầu
A11: Liên kết 1:1 | B11: CHI_NHANH – THU_THU (thủ thư trưởng); DOC_GIA – THE_DOC_GIA | C11: TV2 | D11: Chưa bắt đầu
A12: Liên kết 1:N | B12: PHONG_KHO – GIA_SACH; GIA_SACH – CUON_SACH | C12: TV1 | D12: Chưa bắt đầu
A13: Liên kết N:N có thuộc tính | B13: PHIEU_MUON – CUON_SACH qua CT_MUON (HanTra) | C13: TV3 | D13: Chưa bắt đầu
A14: Liên kết đệ quy | B14: THU_THU quản lý THU_THU | C14: TV2 | D14: Chưa bắt đầu
A15: Liên kết 3 ngôi | B15: THU_THU – DOC_GIA – CUON_SACH trong lần mượn | C15: TV3 | D15: Chưa bắt đầu
... A18: Ràng buộc (min,max) | B18: Phiếu mượn (1,10) cuốn; độc giả (0,50) cuốn đang giữ | C18: TV3 | D18: Chưa bắt đầu

Sheet Thông số kịch bản
A1: Thông số kịch bản nhóm tự quy định
A2: Phạt và tuổi thọ của Truyện, Tham khảo theo đúng đề; các dòng khác nhóm tự đặt. Cột tính toán dùng công thức.
A4: Mã | B4: Thể loại | C4: Hạn mượn (ngày) | D4: Tuổi thọ (năm) | E4: Tuổi thọ (tháng) | F4: Phạt cơ bản/cuốn (đ) | G4: Phạt thêm/ngày (đ) | H4: Ví dụ: trễ 3 ngày (đ)
A5: TR | B5: Truyện | C5: 14 | D5: 15 | E5: =D5*12 -> 180 | F5: 100000 | G5: 10000 | H5: =F5+G5*3 -> 130000
A6: TK | B6: Tài liệu tham khảo | C6: 7 | D6: 10 | E6: =D6*12 -> 120 | F6: 200000 | G6: 30000 | H6: =F6+G6*3 -> 290000
A7: GT | B7: Giáo trình | C7: 30 | D7: 8 | E7: =D7*12 -> 96 | F7: 150000 | G7: 20000 | H7: =F7+G7*3 -> 210000
A8: KH | B8: Khoa học phổ thông | C8: 14 | D8: 12 | E8: =D8*12 -> 144 | F8: 120000 | G8: 15000 | H8: =F8+G8*3 -> 165000
A9: NV | B9: Sách ngoại văn | C9: 21 | D9: 12 | E9: =D9*12 -> 144 | F9: 200000 | G9: 30000 | H9: =F9+G9*3 -> 290000
A10: TC | B10: Tạp chí | C10: 7 | D10: 3 | E10: =D10*12 -> 36 | F10: 50000 | G10: 5000 | H10: =F10+G10*3 -> 65000
A11: Hạn trả = Ngày mượn + COALESCE(DAU_SACH.SoNgayMuonRieng, THE_LOAI.SoNgayMuon). Tiền phạt = phạt cơ bản + phạt/ngày × số ngày trễ. Số màu xanh là giá trị nhập.
A13: Phòng đọc
A14: Loại phòng | B14: Số phòng/chi nhánh | C14: Sức chứa (người) | D14: Giá (đ/giờ) | E14: Số giờ tối thiểu | F14: Số giờ tối đa | G14: Giá tối đa 1 lượt (đ)
A15: Học nhóm | B15: 5 | C15: 4–10 | D15: 50000 | E15: 1 | F15: 4 | G15: =D15*F15 -> 200000
A16: Hội thảo | B16: 2 | C16: 20–60 | D16: 300000 | E16: 2 | F16: 8 | G16: =D16*F16 -> 2400000
A17: Tổng số phòng (3 chi nhánh): | D17: =(B15+B16)*3 -> 21
A19: Luật thuê: giờ tròn, trong 07:00–21:00; đặt trước tối đa 14 ngày; không vượt sức chứa; không trùng giờ; thẻ hết hạn hoặc còn nợ phạt không được thuê.
A21: Khác
A22: Chi nhánh | B22: 3: CN01 Cầu Giấy, CN02 Hà Đông, CN03 Hoàn Kiếm; mở cửa 07:00–21:00
A23: Phòng kho / giá sách | B23: 2 phòng kho mỗi chi nhánh; mỗi giá tối đa 100 cuốn cùng thể loại
A24: Thẻ độc giả | B24: Hiệu lực 1 năm, gia hạn 1 năm; thẻ hết hạn không được mượn
A25: Giới hạn mượn (đề) | B25: Tối đa 10 cuốn mỗi lần; tối đa 50 cuốn đang giữ; trả 1–n cuốn mỗi lần
A26: Thời gian dữ liệu | B26: 01/07/2026 – 30/09/2026 (3 tháng)
A27: Quy mô dữ liệu | B27: 300 đầu sách, 1.500 cuốn, 200 độc giả, 15 thủ thư, ~800 phiếu mượn, 21 phòng đọc, ~150 lượt thuê
A28: Phân tán | B28: 3 site = 3 chi nhánh; minh họa bằng 3 database QLTV_CN01..03 trên cùng server MariaDB
A29: Hệ quản trị | B29: MariaDB 11.4 LTS, InnoDB, utf8mb4 / utf8mb4_unicode_ci

Sheet Lộ trình
A1: Lộ trình và mốc tự kiểm tra
A2: Cả kỳ chỉ 3 cuộc gọi online. Tiến độ báo bằng tin nhắn tối thứ Ba và thứ Sáu.
A4: Ngày | B4: Loại | C4: Nội dung | D4: Ai | E4: Trạng thái
A5: 46310 | B5: Mốc | C5: TV1 gửi ERD khung + schema v0 + thông số kịch bản | D5: TV1 | E5: Chưa bắt đầu
A6: 46313 | B6: Mốc | C6: Hết hạn góp ý schema (im lặng = đồng ý) | D6: Cả nhóm | E6: Chưa bắt đầu
A7: 46314 | B7: Cuộc gọi 1 (45') | C7: Chốt schema v1; TV5 chốt quy ước procedure; ERD con xong | D7: Cả nhóm | E7: Chưa bắt đầu
A8: 46321 | B8: Mốc | C8: PTH, khóa, BCNF xong; DDL mỗi mảng chạy trong build_all.sql | D8: TV1–TV4 | E8: Chưa bắt đầu
A9: 46328 | B9: Mốc | C9: Có dữ liệu mẫu tối thiểu; procedure CRUD của mỗi người chạy được | D9: TV1–TV4 | E9: Chưa bắt đầu
A10: 46335 | B10: Mốc | C10: Đủ 8 trigger, 7 transaction, 6 truy vấn; dữ liệu 3 tháng | D10: Cả nhóm | E10: Chưa bắt đầu
A11: 46339 | B11: Mốc | C11: Phân tán, index, phân quyền, script test xong | D11: TV4, TV5 | E11: Chưa bắt đầu
A12: 46342 | B12: Cuộc gọi 2 (45') | C12: Build từ DB trống không lỗi; các phần báo cáo riêng xong | D12: Cả nhóm | E12: Chưa bắt đầu
A13: 46346 | B13: Nộp | C13: TV1 nộp báo cáo tổng (mục tiêu) | D13: TV1 | E13: Chưa bắt đầu
A14: 46348 | B14: Hạn chót | C14: Hạn nộp của giảng viên (23h59) | D14: — | E14: Chưa bắt đầu
B15: Cuộc gọi 3 (60') | C15: Tập demo đổi vai trước ngày thi | D15: Cả nhóm | E15: Chưa bắt đầu

Sheet Quy ước MariaDB
A1: Quy ước chung và đối chiếu cú pháp
A2: Slide chương 6 viết bằng SQL Server; nhóm cài trên MariaDB.
A4: Nhóm | B4: Mục | C4: Quy ước
A5: Đặt tên | B5: Bảng | C5: CHỮ_HOA_KHÔNG_DẤU: CUON_SACH
A6: Đặt tên | B6: Cột | C6: PascalCase không dấu: MaCuonSach, HanTra
A7: Đặt tên | B7: Ràng buộc | C7: PK_<Bang>, FK_<Bang>_<BangThamChieu>, CK_<Bang>_<Y>, UQ_<Bang>_<Cot> — luôn đặt tên
A8: Đặt tên | B8: Trigger / procedure / function / view | C8: trg_<Bang>_<Viec>, sp_<DoiTuong>_<Viec>, fn_<Viec>, v_<BaoCao>
A9: Đặt tên | B9: Tham số / biến | C9: p_<Ten> cho tham số, v_<Ten> cho biến cục bộ
A10: Lỗi | B10: Mã lỗi | C10: SIGNAL SQLSTATE '45000' SET MESSAGE_TEXT = 'E101: Mỗi lần mượn tối đa 10 cuốn'. E1xx mượn trả, E2xx phòng, E3xx kho, E4xx độc giả
A11: Cú pháp | B11: inserted / deleted | C11: NEW / OLD trong trigger FOR EACH ROW
A12: Cú pháp | B12: INSTEAD OF, ROLLBACK TRANSACTION trong trigger | C12: Trigger BEFORE + SIGNAL SQLSTATE '45000'
A13: Cú pháp | B13: IF UPDATE(cot) | C13: IF NEW.cot <> OLD.cot THEN … END IF
A14: Cú pháp | B14: BEGIN TRAN … COMMIT | C14: START TRANSACTION … COMMIT + DECLARE EXIT HANDLER FOR SQLEXCEPTION BEGIN ROLLBACK; RESIGNAL; END
A15: Cú pháp | B15: @bien, PRINT, THROW | C15: DECLARE v_bien, tham số p_, SIGNAL
... A28: Thư mục | B28: Khác | C28: erd/, phan_tan/, app/, baocao/, docs/

Sheet Báo cáo Word
A1: Phân công viết báo cáo (1 file Word/PDF duy nhất)
A2: Mỗi người viết file riêng theo style Heading 1–3 của file mẫu TV1; TV1 ghép.
A4: Mục | B4: Nội dung | C4: Người viết | D4: Ghi chú | E4: Hạn | F4: Trạng thái
A5: 1 | B5: Phân tích yêu cầu dữ liệu và ứng dụng | C5: TV1 | D5: TV2–TV4 gửi mỗi người 1 đoạn về mảng mình | E5: 46342 | F5: Chưa bắt đầu
A6: 2 | B6: Lược đồ E-R và mô tả | C6: TV1 (ERD tổng) + mỗi người mô tả thực thể của mình | D6: — | E6: 46342 | F6: Chưa bắt đầu
A7: 3 | B7: Lược đồ quan hệ, PTH, khóa, BCNF | C7: TV1–TV4 (bảng của mình) | D7: — | E7: 46342 | F7: Chưa bắt đầu
A8: 4 | B8: Cài đặt, dữ liệu, ràng buộc, giao diện | C8: Cả 5 người (mảng mình) | D8: TV3: ràng buộc số lượng bản ghi; TV5: truy vấn, tối ưu, bảo mật, giao diện; TV2: minh chứng dữ liệu | E8: 46342 | F8: Chưa bắt đầu
A9: 5 | B9: Thiết kế CSDL phân tán | C9: TV4 | D9: — | E9: 46342 | F9: Chưa bắt đầu
A10: — | B10: Ghép, mục lục, kiểm tra định dạng, nộp | C10: TV1 | D10: Nộp trước 20/11 (hạn 22/11) | E10: 46346 | F10: Chưa bắt đầu

Sheet Thành viên
A1: Thành viên nhóm
A2: Nhập họ tên thật vào ô vàng; các sheet khác tự lấy tên từ đây.
A3: Mã TV | B3: Họ tên | C3: Mảng phụ trách | D3: Người review mình | E3: Liên lạc (Zalo/email)
A4: TV1 | C4: Kho sách + trưởng nhóm (đại diện liên hệ GV) | D4: TV3
A5: TV2 | C5: Con người, chi nhánh, dữ liệu 3 tháng | D5: TV4
A6: TV3 | C6: Mượn – trả – phạt | D6: TV1
A7: TV4 | C7: Phòng đọc + CSDL phân tán | D7: TV5
A8: TV5 | C8: Truy vấn, tối ưu, bảo mật, kiểm thử, giao diện tối giản | D8: TV2
