Workbook

Sheet Hướng dẫn
A1: Phân việc 5 thành viên – BTL Xây dựng hệ thống quản lý thư viện (MariaDB)
A3: Mỗi thành viên phụ trách trọn một mảng nghiệp vụ: từ yêu cầu, ERD, bảng, ràng buộc, trigger, transaction đến giao diện và ca kiểm thử của mảng đó.
A4: Cách dùng:
A5: 1. Vào sheet 'Thành viên', điền họ tên, mã học viên, liên lạc vào các ô nền vàng (ví dụ: Nguyễn Văn A | B25CHHT001 | 09xx xxx xxx). Các sheet khác tự lấy họ tên theo mã TV.
A6: 2. Sheet 'Phân việc' là danh sách đầu việc của từng người. Cột 'Mức nắm' (nền vàng) chọn Chưa đọc / Đang học / Đã nắm để theo dõi việc chuẩn bị thuyết trình.
A7: 3. Sheet 'Tổng hợp' tự đếm khối lượng của từng người và kiểm tra tổng có khớp số đối tượng thật trong CSDL không.
A8: 4. Muốn đổi người phụ trách một mục: sửa mã ở cột 'TV' (chọn trong danh sách TV1–TV5); họ tên và bảng tổng hợp tự cập nhật.
A10: Các sheet:
A11: Thành viên – mã TV, họ tên, mảng phụ trách, người review chéo
A12: Tổng hợp – số đầu việc, bảng, trigger, transaction, function, procedure, mục báo cáo, ca kiểm thử, thao tác giao diện của từng người
A13: Phân việc – đầu việc cụ thể, file sản phẩm, mục báo cáo tương ứng, người review
A14: Đối tượng CSDL – 23 bảng, 18 trigger, 7 transaction, 8 function, 40 procedure khác, event, view, chỉ mục, vai trò và người phụ trách
... A21: Ô nền vàng là ô cần điền. Số liệu lấy từ mã nguồn và báo cáo hiện tại (tai_lieu/BaoCao_BTL_QLTV.docx).

Sheet Thành viên
A1: Thành viên nhóm
A2: Điền họ tên, mã học viên, liên lạc vào ô nền vàng. Các sheet khác tự lấy họ tên theo mã TV. Người review là người thứ hai phải trả lời được câu hỏi về phần đó.
A4: Ví dụ cách điền: Họ tên 'Nguyễn Văn A', mã học viên 'B25CHHT001', liên lạc 'Zalo 09xx xxx xxx'.
A5: Mã TV | B5: Họ tên | C5: Mã học viên | D5: Mảng phụ trách | E5: Phần chung của báo cáo | F5: Người review | G5: Liên lạc
A6: TV1 | D6: Sách và kho, trưởng nhóm | E6: Lời mở đầu, 1.1–1.3, chương 2, 4.6, kết luận | F6: TV3
A7: TV2 | D7: Con người, chi nhánh, dữ liệu 3 tháng | E7: Chương 3, 4.3, 4.4 | F7: TV4
A8: TV3 | D8: Mượn, trả, phạt | E8: 1.4, 4.5, 4.7 | F8: TV1
A9: TV4 | D9: Phòng đọc và CSDL phân tán | E9: Chương 5 | F9: TV5
A10: TV5 | D10: Truy vấn, tối ưu, bảo mật, kiểm thử, giao diện | E10: 4.1–4.2, 4.8–4.13 | F10: TV2

Sheet Tổng hợp
A1: Tổng hợp khối lượng theo người
A2: Tự đếm từ các sheet khác. Dòng 'Số thực tế trong CSDL' lấy từ mã nguồn hiện tại; dòng 'Kiểm tra' báo Khớp khi đã chia hết, không sót, không trùng.
A4: TV | B4: Họ tên | C4: Đầu việc | D4: Đã nắm | E4: % đã nắm | F4: Bảng | G4: Trigger | H4: Transaction | I4: Function | J4: Procedure khác | K4: Mã lỗi | L4: Mục báo cáo | M4: Ca kiểm thử | N4: Thao tác giao diện
A5: TV1 | B5: =IFERROR(INDEX('Thành viên'!$B$6:$B$10,MATCH($A5,'Thành viên'!$A$6:$A$10,0))&"","") | C5: =COUNTIF('Phân việc'!$B$5:$B$43,$A5) -> 9 | D5: =COUNTIFS('Phân việc'!$B$5:$B$43,$A5,'Phân việc'!$I$5:$I$43,"Đã nắm") -> 0 | E5: =IF(C5=0,0,D5/C5) -> 0 | F5: =COUNTIFS('Đối tượng CSDL'!$A$5:$A$114,"Bảng",'Đối tượng CSDL'!$D$5:$D$114,$A5) -> 8 | G5: =COUNTIFS('Đối tượng CSDL'!$A$5:$A$114,"Trigger",'Đối tượng CSDL'!$D$5:$D$114,$A5) -> 6 | H5: =COUNTIFS('Đối tượng CSDL'!$A$5:$A$114,"Transaction",'Đối tượng CSDL'!$D$5:$D$114,$A5) -> 2 | I5: =COUNTIFS('Đối tượng CSDL'!$A$5:$A$114,"Function",'Đối tượng CSDL'!$D$5:$D$114,$A5) -> 0 | J5: =COUNTIFS('Đối tượng CSDL'!$A$5:$A$114,"Procedure",'Đối tượng CSDL'!$D$5:$D$114,$A5) -> 16 | K5: =COUNTIF('Mã lỗi'!$D$5:$D$34,$A5) -> 6 | L5: =COUNTIF('Mục báo cáo'!$C$5:$C$56,$A5) -> 16 | M5: =COUNTIF('Kiểm thử SQL'!$C$5:$C$56,$A5) -> 15 | N5: =COUNTIF('Giao diện'!$F$5:$F$27,$A5) -> 7
A6: TV2 | B6: =IFERROR(INDEX('Thành viên'!$B$6:$B$10,MATCH($A6,'Thành viên'!$A$6:$A$10,0))&"","") | C6: =COUNTIF('Phân việc'!$B$5:$B$43,$A6) -> 8 | D6: =COUNTIFS('Phân việc'!$B$5:$B$43,$A6,'Phân việc'!$I$5:$I$43,"Đã nắm") -> 0 | E6: =IF(C6=0,0,D6/C6) -> 0 | F6: =COUNTIFS('Đối tượng CSDL'!$A$5:$A$114,"Bảng",'Đối tượng CSDL'!$D$5:$D$114,$A6) -> 6 | G6: =COUNTIFS('Đối tượng CSDL'!$A$5:$A$114,"Trigger",'Đối tượng CSDL'!$D$5:$D$114,$A6) -> 4 | H6: =COUNTIFS('Đối tượng CSDL'!$A$5:$A$114,"Transaction",'Đối tượng CSDL'!$D$5:$D$114,$A6) -> 1 | I6: =COUNTIFS('Đối tượng CSDL'!$A$5:$A$114,"Function",'Đối tượng CSDL'!$D$5:$D$114,$A6) -> 3 | J6: =COUNTIFS('Đối tượng CSDL'!$A$5:$A$114,"Procedure",'Đối tượng CSDL'!$D$5:$D$114,$A6) -> 12 | K6: =COUNTIF('Mã lỗi'!$D$5:$D$34,$A6) -> 8 | L6: =COUNTIF('Mục báo cáo'!$C$5:$C$56,$A6) -> 10 | M6: =COUNTIF('Kiểm thử SQL'!$C$5:$C$56,$A6) -> 9 | N6: =COUNTIF('Giao diện'!$F$5:$F$27,$A6) -> 9
A7: TV3 | B7: =IFERROR(INDEX('Thành viên'!$B$6:$B$10,MATCH($A7,'Thành viên'!$A$6:$A$10,0))&"","") | C7: =COUNTIF('Phân việc'!$B$5:$B$43,$A7) -> 7 | D7: =COUNTIFS('Phân việc'!$B$5:$B$43,$A7,'Phân việc'!$I$5:$I$43,"Đã nắm") -> 0 | E7: =IF(C7=0,0,D7/C7) -> 0 | F7: =COUNTIFS('Đối tượng CSDL'!$A$5:$A$114,"Bảng",'Đối tượng CSDL'!$D$5:$D$114,$A7) -> 6 | G7: =COUNTIFS('Đối tượng CSDL'!$A$5:$A$114,"Trigger",'Đối tượng CSDL'!$D$5:$D$114,$A7) -> 6 | H7: =COUNTIFS('Đối tượng CSDL'!$A$5:$A$114,"Transaction",'Đối tượng CSDL'!$D$5:$D$114,$A7) -> 3 | I7: =COUNTIFS('Đối tượng CSDL'!$A$5:$A$114,"Function",'Đối tượng CSDL'!$D$5:$D$114,$A7) -> 4 | J7: =COUNTIFS('Đối tượng CSDL'!$A$5:$A$114,"Procedure",'Đối tượng CSDL'!$D$5:$D$114,$A7) -> 0 | K7: =COUNTIF('Mã lỗi'!$D$5:$D$34,$A7) -> 11 | L7: =COUNTIF('Mục báo cáo'!$C$5:$C$56,$A7) -> 3 | M7: =COUNTIF('Kiểm thử SQL'!$C$5:$C$56,$A7) -> 15 | N7: =COUNTIF('Giao diện'!$F$5:$F$27,$A7) -> 4
A8: TV4 | B8: =IFERROR(INDEX('Thành viên'!$B$6:$B$10,MATCH($A8,'Thành viên'!$A$6:$A$10,0))&"","") | C8: =COUNTIF('Phân việc'!$B$5:$B$43,$A8) -> 8 | D8: =COUNTIFS('Phân việc'!$B$5:$B$43,$A8,'Phân việc'!$I$5:$I$43,"Đã nắm") -> 0 | E8: =IF(C8=0,0,D8/C8) -> 0 | F8: =COUNTIFS('Đối tượng CSDL'!$A$5:$A$114,"Bảng",'Đối tượng CSDL'!$D$5:$D$114,$A8) -> 3 | G8: =COUNTIFS('Đối tượng CSDL'!$A$5:$A$114,"Trigger",'Đối tượng CSDL'!$D$5:$D$114,$A8) -> 2 | H8: =COUNTIFS('Đối tượng CSDL'!$A$5:$A$114,"Transaction",'Đối tượng CSDL'!$D$5:$D$114,$A8) -> 1 | I8: =COUNTIFS('Đối tượng CSDL'!$A$5:$A$114,"Function",'Đối tượng CSDL'!$D$5:$D$114,$A8) -> 1 | J8: =COUNTIFS('Đối tượng CSDL'!$A$5:$A$114,"Procedure",'Đối tượng CSDL'!$D$5:$D$114,$A8) -> 5 | K8: =COUNTIF('Mã lỗi'!$D$5:$D$34,$A8) -> 5 | L8: =COUNTIF('Mục báo cáo'!$C$5:$C$56,$A8) -> 9 | M8: =COUNTIF('Kiểm thử SQL'!$C$5:$C$56,$A8) -> 9 | N8: =COUNTIF('Giao diện'!$F$5:$F$27,$A8) -> 3
A9: TV5 | B9: =IFERROR(INDEX('Thành viên'!$B$6:$B$10,MATCH($A9,'Thành viên'!$A$6:$A$10,0))&"","") | C9: =COUNTIF('Phân việc'!$B$5:$B$43,$A9) -> 7 | D9: =COUNTIFS('Phân việc'!$B$5:$B$43,$A9,'Phân việc'!$I$5:$I$43,"Đã nắm") -> 0 | E9: =IF(C9=0,0,D9/C9) -> 0 | F9: =COUNTIFS('Đối tượng CSDL'!$A$5:$A$114,"Bảng",'Đối tượng CSDL'!$D$5:$D$114,$A9) -> 0 | G9: =COUNTIFS('Đối tượng CSDL'!$A$5:$A$114,"Trigger",'Đối tượng CSDL'!$D$5:$D$114,$A9) -> 0 | H9: =COUNTIFS('Đối tượng CSDL'!$A$5:$A$114,"Transaction",'Đối tượng CSDL'!$D$5:$D$114,$A9) -> 0 | I9: =COUNTIFS('Đối tượng CSDL'!$A$5:$A$114,"Function",'Đối tượng CSDL'!$D$5:$D$114,$A9) -> 0 | J9: =COUNTIFS('Đối tượng CSDL'!$A$5:$A$114,"Procedure",'Đối tượng CSDL'!$D$5:$D$114,$A9) -> 7 | K9: =COUNTIF('Mã lỗi'!$D$5:$D$34,$A9) -> 0 | L9: =COUNTIF('Mục báo cáo'!$C$5:$C$56,$A9) -> 8 | M9: =COUNTIF('Kiểm thử SQL'!$C$5:$C$56,$A9) -> 4 | N9: =COUNTIF('Giao diện'!$F$5:$F$27,$A9) -> 0
A10: Tổng | C10: =SUM(C5:C9) -> 39 | D10: =SUM(D5:D9) -> 0 | E10: =IF(C10=0,0,D10/C10) -> 0 | F10: =SUM(F5:F9) -> 23 | G10: =SUM(G5:G9) -> 18 | H10: =SUM(H5:H9) -> 7 | I10: =SUM(I5:I9) -> 8 | J10: =SUM(J5:J9) -> 40 | K10: =SUM(K5:K9) -> 30 | L10: =SUM(L5:L9) -> 46 | M10: =SUM(M5:M9) -> 52 | N10: =SUM(N5:N9) -> 23
A11: Số thực tế trong CSDL | F11: 23 | G11: 18 | H11: 7 | I11: 8 | J11: 40 | K11: 30 | M11: 52 | N11: 23
A12: Kiểm tra | F12: =IF(F10=F11,"Khớp","Lệch") -> Khớp | G12: =IF(G10=G11,"Khớp","Lệch") -> Khớp | H12: =IF(H10=H11,"Khớp","Lệch") -> Khớp | I12: =IF(I10=I11,"Khớp","Lệch") -> Khớp | J12: =IF(J10=J11,"Khớp","Lệch") -> Khớp | K12: =IF(K10=K11,"Khớp","Lệch") -> Khớp | M12: =IF(M10=M11,"Khớp","Lệch") -> Khớp | N12: =IF(N10=N11,"Khớp","Lệch") -> Khớp
A14: Procedure khác = 47 procedure − 7 transaction = 40. Số thực tế đếm từ 01–07 *.sql và 08_test.sql ngày lập file; số mã lỗi lấy từ mục 4.12 của báo cáo.
A15: Đầu việc và Mục báo cáo không có số chuẩn để so vì có thể thêm bớt tùy nhóm.

Sheet Phân việc
A1: Phân việc chi tiết
A2: Mỗi dòng là một đầu việc. Cột 'Mức nắm' và 'Ghi chú' (nền vàng) do từng người tự cập nhật.
A4: Mã việc | B4: TV | C4: Họ tên | D4: Nhóm việc | E4: Đầu việc | F4: Sản phẩm / file | G4: Mục báo cáo | H4: Review | I4: Mức nắm | J4: Ghi chú
A5: TV1-01 | B5: TV1 | C5: =IFERROR(INDEX('Thành viên'!$B$6:$B$10,MATCH($B5,'Thành viên'!$A$6:$A$10,0))&"","") | D5: Phân tích | E5: Mô tả nghiệp vụ, thông tin cần lưu, ứng dụng triển khai | F5: P1_phan_tich_ERD.md | G5: 1.1–1.3 | H5: TV3 | I5: Chưa đọc
A6: TV1-02 | B6: TV1 | C6: =IFERROR(INDEX('Thành viên'!$B$6:$B$10,MATCH($B6,'Thành viên'!$A$6:$A$10,0))&"","") | D6: Thiết kế | E6: ERD tổng: tập thực thể, liên kết, đối chiếu đủ các loại, ký hiệu sơ đồ | F6: erd/erd.drawio | G6: 2.1–2.4 | H6: TV3 | I6: Chưa đọc
A7: TV1-03 | B7: TV1 | C7: =IFERROR(INDEX('Thành viên'!$B$6:$B$10,MATCH($B7,'Thành viên'!$A$6:$A$10,0))&"","") | D7: Cài đặt SQL | E7: 8 bảng mảng sách và kho, ràng buộc CHECK/FK/UNIQUE | F7: 01_schema.sql | G7: 3.2, 4.4 | H7: TV3 | I7: Chưa đọc
A8: TV1-04 | B8: TV1 | C8: =IFERROR(INDEX('Thành viên'!$B$6:$B$10,MATCH($B8,'Thành viên'!$A$6:$A$10,0))&"","") | D8: Cài đặt SQL | E8: 15 procedure thêm/sửa/xóa/tìm phòng kho, giá, đầu sách, cuốn sách | F8: 02_function_procedure.sql | G8: 4.6 | H8: TV3 | I8: Chưa đọc
A9: TV1-05 | B9: TV1 | C9: =IFERROR(INDEX('Thành viên'!$B$6:$B$10,MATCH($B9,'Thành viên'!$A$6:$A$10,0))&"","") | D9: Cài đặt SQL | E9: Trigger TRG4 (đếm sách trên giá), TRG5 (tuổi thọ khi mượn), TRG6 (đúng giá, giá đầy) | F9: 03_trigger.sql | G9: 4.5, 4.7 | H9: TV3 | I9: Chưa đọc
A10: TV1-06 | B10: TV1 | C10: =IFERROR(INDEX('Thành viên'!$B$6:$B$10,MATCH($B10,'Thành viên'!$A$6:$A$10,0))&"","") | D10: Cài đặt SQL | E10: TX4 nhập lô sách, TX5 thanh lý sách hết niên hạn | F10: 04_transaction.sql | G10: 4.7 | H10: TV3 | I10: Chưa đọc
A11: TV1-07 | B11: TV1 | C11: =IFERROR(INDEX('Thành viên'!$B$6:$B$10,MATCH($B11,'Thành viên'!$A$6:$A$10,0))&"","") | D11: Cài đặt SQL | E11: Tuổi thọ giảm theo thời gian: sp_CapNhatTuoiTho và event chạy mỗi ngày | F11: 02_function_procedure.sql | G11: 4.6, 4.7 | H11: TV3 | I11: Chưa đọc
A12: TV1-08 | B12: TV1 | C12: =IFERROR(INDEX('Thành viên'!$B$6:$B$10,MATCH($B12,'Thành viên'!$A$6:$A$10,0))&"","") | D12: Giao diện | E12: Trang Sách & kho: phòng kho, giá sách, xóa cuốn sách | F12: app/app.py | G12: 4.13 | H12: TV3 | I12: Chưa đọc
A13: TV1-09 | B13: TV1 | C13: =IFERROR(INDEX('Thành viên'!$B$6:$B$10,MATCH($B13,'Thành viên'!$A$6:$A$10,0))&"","") | D13: Báo cáo | E13: Lời mở đầu, kết luận, ghép báo cáo Word | F13: baocao/assemble.py, build_docx.js | G13: Mở đầu, Kết luận | H13: TV3 | I13: Chưa đọc
A14: TV2-01 | B14: TV2 | C14: =IFERROR(INDEX('Thành viên'!$B$6:$B$10,MATCH($B14,'Thành viên'!$A$6:$A$10,0))&"","") | D14: Cài đặt SQL | E14: 6 bảng con người và chi nhánh: ISA, quan_ly đệ quy, khóa ngoại vòng trưởng chi nhánh | F14: 01_schema.sql | G14: 3.2, 4.4 | H14: TV4 | I14: Chưa đọc
A15: TV2-02 | B15: TV2 | C15: =IFERROR(INDEX('Thành viên'!$B$6:$B$10,MATCH($B15,'Thành viên'!$A$6:$A$10,0))&"","") | D15: Cài đặt SQL | E15: fn_Tuoi, fn_TheConHan, fn_MaNguoiMoi và 12 procedure chi nhánh, độc giả, thủ thư | F15: 02_function_procedure.sql | G15: 4.6 | H15: TV4 | I15: Chưa đọc
A16: TV2-03 | B16: TV2 | C16: =IFERROR(INDEX('Thành viên'!$B$6:$B$10,MATCH($B16,'Thành viên'!$A$6:$A$10,0))&"","") | D16: Cài đặt SQL | E16: Trigger TRG8 (toàn vẹn độc giả, ISA), TX6 đăng ký độc giả | F16: 03_trigger.sql, 04_transaction.sql | G16: 4.5, 4.7 | H16: TV4 | I16: Chưa đọc
... A43: TV5-07 | B43: TV5 | C43: =IFERROR(INDEX('Thành viên'!$B$6:$B$10,MATCH($B43,'Thành viên'!$A$6:$A$10,0))&"","") | D43: Giao diện | E43: Khung giao diện, kết nối CSDL, kiểm thử tự động 23 thao tác, trang Báo cáo | F43: app/app.py, db.py, chup_man_hinh.py | G43: 4.13 | H43: TV2 | I43: Chưa đọc

Sheet Đối tượng CSDL
A1: Đối tượng trong CSDL QLTV và người phụ trách
A2: Mỗi đối tượng thuộc đúng một người. Loại 'Transaction' là 7 procedure TX1–TX7; 'Procedure' là 40 procedure còn lại (tổng 47).
A4: Loại | B4: Tên | C4: Mô tả | D4: TV | E4: Họ tên | F4: File
A5: Bảng | B5: CHI_NHANH | C5: Chi nhánh thư viện | D5: TV2 | E5: =IFERROR(INDEX('Thành viên'!$B$6:$B$10,MATCH($D5,'Thành viên'!$A$6:$A$10,0))&"","") | F5: 01_schema.sql
A6: Bảng | B6: NGUOI | C6: Người – lớp cha của độc giả và thủ thư (ISA) | D6: TV2 | E6: =IFERROR(INDEX('Thành viên'!$B$6:$B$10,MATCH($D6,'Thành viên'!$A$6:$A$10,0))&"","") | F6: 01_schema.sql
A7: Bảng | B7: SDT_NGUOI | C7: Số điện thoại của người (thuộc tính đa trị) | D7: TV2 | E7: =IFERROR(INDEX('Thành viên'!$B$6:$B$10,MATCH($D7,'Thành viên'!$A$6:$A$10,0))&"","") | F7: 01_schema.sql
A8: Bảng | B8: DOC_GIA | C8: Độc giả (lớp con) | D8: TV2 | E8: =IFERROR(INDEX('Thành viên'!$B$6:$B$10,MATCH($D8,'Thành viên'!$A$6:$A$10,0))&"","") | F8: 01_schema.sql
A9: Bảng | B9: THE_DOC_GIA | C9: Thẻ độc giả | D9: TV2 | E9: =IFERROR(INDEX('Thành viên'!$B$6:$B$10,MATCH($D9,'Thành viên'!$A$6:$A$10,0))&"","") | F9: 01_schema.sql
A10: Bảng | B10: THU_THU | C10: Thủ thư (lớp con) | D10: TV2 | E10: =IFERROR(INDEX('Thành viên'!$B$6:$B$10,MATCH($D10,'Thành viên'!$A$6:$A$10,0))&"","") | F10: 01_schema.sql
A11: Bảng | B11: THE_LOAI | C11: Thể loại sách | D11: TV1 | E11: =IFERROR(INDEX('Thành viên'!$B$6:$B$10,MATCH($D11,'Thành viên'!$A$6:$A$10,0))&"","") | F11: 01_schema.sql
A12: Bảng | B12: BANG_PHI_PHAT | C12: Biểu phí phạt theo thể loại (thực thể yếu) | D12: TV3 | E12: =IFERROR(INDEX('Thành viên'!$B$6:$B$10,MATCH($D12,'Thành viên'!$A$6:$A$10,0))&"","") | F12: 01_schema.sql
A13: Bảng | B13: TAC_GIA | C13: Tác giả | D13: TV1 | E13: =IFERROR(INDEX('Thành viên'!$B$6:$B$10,MATCH($D13,'Thành viên'!$A$6:$A$10,0))&"","") | F13: 01_schema.sql
A14: Bảng | B14: DAU_SACH | C14: Đầu sách | D14: TV1 | E14: =IFERROR(INDEX('Thành viên'!$B$6:$B$10,MATCH($D14,'Thành viên'!$A$6:$A$10,0))&"","") | F14: 01_schema.sql
A15: Bảng | B15: DAU_SACH_TAC_GIA | C15: Liên kết N:N đầu sách – tác giả | D15: TV1 | E15: =IFERROR(INDEX('Thành viên'!$B$6:$B$10,MATCH($D15,'Thành viên'!$A$6:$A$10,0))&"","") | F15: 01_schema.sql
A16: Bảng | B16: PHONG_KHO | C16: Phòng đựng sách | D16: TV1 | E16: =IFERROR(INDEX('Thành viên'!$B$6:$B$10,MATCH($D16,'Thành viên'!$A$6:$A$10,0))&"","") | F16: 01_schema.sql
... A114: Vai trò | B114: r_QuanLy | C114: Kế thừa r_ThuThu, thực thi mọi procedure, đọc mọi bảng | D114: TV5 | E114: =IFERROR(INDEX('Thành viên'!$B$6:$B$10,MATCH($D114,'Thành viên'!$A$6:$A$10,0))&"","") | F114: 07_index_baomat.sql

Sheet Mã lỗi
A1: Bảng mã lỗi nghiệp vụ
A2: E1xx mượn trả (TV3), E2xx phòng đọc (TV4), E3xx sách và kho (TV1), E4xx độc giả và thủ thư (TV2).
A4: Mã | B4: Ý nghĩa | C4: Nơi phát sinh | D4: TV | E4: Họ tên
A5: E100 | B5: Phiếu mượn/trả không có cuốn nào | C5: TX1, TX2 | D5: TV3 | E5: =IFERROR(INDEX('Thành viên'!$B$6:$B$10,MATCH($D5,'Thành viên'!$A$6:$A$10,0))&"","")
A6: E101 | B6: Quá 10 cuốn mỗi lần mượn | C6: TRG1, TX1 | D6: TV3 | E6: =IFERROR(INDEX('Thành viên'!$B$6:$B$10,MATCH($D6,'Thành viên'!$A$6:$A$10,0))&"","")
A7: E102 | B7: Độc giả đã giữ 50 cuốn | C7: TRG2 | D7: TV3 | E7: =IFERROR(INDEX('Thành viên'!$B$6:$B$10,MATCH($D7,'Thành viên'!$A$6:$A$10,0))&"","")
A8: E103 | B8: Thẻ hết hạn | C8: TX1, TX7 | D8: TV3 | E8: =IFERROR(INDEX('Thành viên'!$B$6:$B$10,MATCH($D8,'Thành viên'!$A$6:$A$10,0))&"","")
A9: E104 | B9: Cuốn không có trên giá, hoặc bị lặp trong danh sách mượn | C9: TRG2, TX1 | D9: TV3 | E9: =IFERROR(INDEX('Thành viên'!$B$6:$B$10,MATCH($D9,'Thành viên'!$A$6:$A$10,0))&"","")
A10: E105 | B10: Ngày trả trước ngày mượn | C10: TRG3 | D10: TV3 | E10: =IFERROR(INDEX('Thành viên'!$B$6:$B$10,MATCH($D10,'Thành viên'!$A$6:$A$10,0))&"","")
A11: E106 | B11: Sửa phiếu trả của dòng đã trả | C11: TRG3 | D11: TV3 | E11: =IFERROR(INDEX('Thành viên'!$B$6:$B$10,MATCH($D11,'Thành viên'!$A$6:$A$10,0))&"","")
A12: E107 | B12: Phiếu trả và phiếu mượn khác độc giả | C12: TRG3 | D12: TV3 | E12: =IFERROR(INDEX('Thành viên'!$B$6:$B$10,MATCH($D12,'Thành viên'!$A$6:$A$10,0))&"","")
A13: E108 | B13: Cuốn không do độc giả mượn hoặc đã trả | C13: TX2 | D13: TV3 | E13: =IFERROR(INDEX('Thành viên'!$B$6:$B$10,MATCH($D13,'Thành viên'!$A$6:$A$10,0))&"","")
A14: E109 | B14: Không có khoản phạt chưa thanh toán | C14: TX3 | D14: TV3 | E14: =IFERROR(INDEX('Thành viên'!$B$6:$B$10,MATCH($D14,'Thành viên'!$A$6:$A$10,0))&"","")
A15: E110 | B15: Còn nợ phạt, không được thuê phòng | C15: TX7 | D15: TV3 | E15: =IFERROR(INDEX('Thành viên'!$B$6:$B$10,MATCH($D15,'Thành viên'!$A$6:$A$10,0))&"","")
A16: E201 | B16: Phòng trùng giờ | C16: TRG7 | D16: TV4 | E16: =IFERROR(INDEX('Thành viên'!$B$6:$B$10,MATCH($D16,'Thành viên'!$A$6:$A$10,0))&"","")
... A34: E408 | B34: Độc giả phải có ít nhất 1 SĐT | C34: TX6 | D34: TV2 | E34: =IFERROR(INDEX('Thành viên'!$B$6:$B$10,MATCH($D34,'Thành viên'!$A$6:$A$10,0))&"","")

Sheet Mục báo cáo
A1: Mục báo cáo và người trình bày
A2: Theo mục lục của tai_lieu/BaoCao_BTL_QLTV.docx. Phụ lục A là mã nguồn SQL ghép tự động.
A4: Mục | B4: Tiêu đề | C4: TV | D4: Họ tên
B5: Lời mở đầu | C5: TV1 | D5: =IFERROR(INDEX('Thành viên'!$B$6:$B$10,MATCH($C5,'Thành viên'!$A$6:$A$10,0))&"","")
A6: CHƯƠNG 1. PHÂN TÍCH YÊU CẦU
A7: 1.1 | B7: Mô tả nghiệp vụ | C7: TV1 | D7: =IFERROR(INDEX('Thành viên'!$B$6:$B$10,MATCH($C7,'Thành viên'!$A$6:$A$10,0))&"","")
A8: 1.2 | B8: Thông tin cần lưu trữ | C8: TV1 | D8: =IFERROR(INDEX('Thành viên'!$B$6:$B$10,MATCH($C8,'Thành viên'!$A$6:$A$10,0))&"","")
A9: 1.3 | B9: Các ứng dụng triển khai trên CSDL | C9: TV1 | D9: =IFERROR(INDEX('Thành viên'!$B$6:$B$10,MATCH($C9,'Thành viên'!$A$6:$A$10,0))&"","")
A10: 1.4 | B10: Ràng buộc về số lượng bản ghi | C10: TV3 | D10: =IFERROR(INDEX('Thành viên'!$B$6:$B$10,MATCH($C10,'Thành viên'!$A$6:$A$10,0))&"","")
A11: CHƯƠNG 2. LƯỢC ĐỒ THỰC THỂ – LIÊN KẾT
A12: 2.1 | B12: Tập thực thể | C12: TV1 | D12: =IFERROR(INDEX('Thành viên'!$B$6:$B$10,MATCH($C12,'Thành viên'!$A$6:$A$10,0))&"","")
A13: 2.2 | B13: Liên kết | C13: TV1 | D13: =IFERROR(INDEX('Thành viên'!$B$6:$B$10,MATCH($C13,'Thành viên'!$A$6:$A$10,0))&"","")
A14: 2.3 | B14: Đối chiếu yêu cầu "đầy đủ các loại" của đề | C14: TV1 | D14: =IFERROR(INDEX('Thành viên'!$B$6:$B$10,MATCH($C14,'Thành viên'!$A$6:$A$10,0))&"","")
A15: 2.4 | B15: Sơ đồ E-R | C15: TV1 | D15: =IFERROR(INDEX('Thành viên'!$B$6:$B$10,MATCH($C15,'Thành viên'!$A$6:$A$10,0))&"","")
A16: CHƯƠNG 3. LƯỢC ĐỒ QUAN HỆ VÀ CHUẨN HÓA
A17: 3.1 | B17: Quy tắc ánh xạ đã dùng | C17: TV2 | D17: =IFERROR(INDEX('Thành viên'!$B$6:$B$10,MATCH($C17,'Thành viên'!$A$6:$A$10,0))&"","")
A18: 3.2 | B18: Tập lược đồ quan hệ (23 quan hệ) | C18: TV2 | D18: =IFERROR(INDEX('Thành viên'!$B$6:$B$10,MATCH($C18,'Thành viên'!$A$6:$A$10,0))&"","")
A19: 3.3 | B19: Phụ thuộc hàm, khóa và kiểm tra BCNF từng lược đồ | C19: TV2 | D19: =IFERROR(INDEX('Thành viên'!$B$6:$B$10,MATCH($C19,'Thành viên'!$A$6:$A$10,0))&"","")
A20: 3.4 | B20: Thuộc tính dẫn xuất được lưu | C20: TV2 | D20: =IFERROR(INDEX('Thành viên'!$B$6:$B$10,MATCH($C20,'Thành viên'!$A$6:$A$10,0))&"","")
A21: 3.5 | B21: Ví dụ quá trình chuẩn hóa từ dạng chưa chuẩn | C21: TV2 | D21: =IFERROR(INDEX('Thành viên'!$B$6:$B$10,MATCH($C21,'Thành viên'!$A$6:$A$10,0))&"","")
A22: 3.6 | B22: Ví dụ tìm phủ tối thiểu (thuật toán MinCover) | C22: TV2 | D22: =IFERROR(INDEX('Thành viên'!$B$6:$B$10,MATCH($C22,'Thành viên'!$A$6:$A$10,0))&"","")
A23: 3.7 | B23: Sơ đồ lược đồ quan hệ | C23: TV2 | D23: =IFERROR(INDEX('Thành viên'!$B$6:$B$10,MATCH($C23,'Thành viên'!$A$6:$A$10,0))&"","")
A24: 3.8 | B24: Từ điển dữ liệu | C24: TV2 | D24: =IFERROR(INDEX('Thành viên'!$B$6:$B$10,MATCH($C24,'Thành viên'!$A$6:$A$10,0))&"","")
A25: CHƯƠNG 4. CÀI ĐẶT CƠ SỞ DỮ LIỆU VÀ ỨNG DỤNG
A26: 4.1 | B26: Môi trường và quy trình cài đặt | C26: TV5 | D26: =IFERROR(INDEX('Thành viên'!$B$6:$B$10,MATCH($C26,'Thành viên'!$A$6:$A$10,0))&"","")
A27: 4.2 | B27: Một số lưu ý khi cài đặt trên MariaDB | C27: TV5 | D27: =IFERROR(INDEX('Thành viên'!$B$6:$B$10,MATCH($C27,'Thành viên'!$A$6:$A$10,0))&"","")
A28: 4.3 | B28: Minh chứng dữ liệu đã nạp | C28: TV2 | D28: =IFERROR(INDEX('Thành viên'!$B$6:$B$10,MATCH($C28,'Thành viên'!$A$6:$A$10,0))&"","")
A29: 4.4 | B29: Toàn bộ ràng buộc toàn vẹn cài đặt bằng SQL | C29: TV2 | D29: =IFERROR(INDEX('Thành viên'!$B$6:$B$10,MATCH($C29,'Thành viên'!$A$6:$A$10,0))&"","")
A30: 4.5 | B30: Danh sách trigger | C30: TV3 | D30: =IFERROR(INDEX('Thành viên'!$B$6:$B$10,MATCH($C30,'Thành viên'!$A$6:$A$10,0))&"","")
A31: 4.6 | B31: Danh sách function và stored procedure | C31: TV1 | D31: =IFERROR(INDEX('Thành viên'!$B$6:$B$10,MATCH($C31,'Thành viên'!$A$6:$A$10,0))&"","")
A32: 4.7 | B32: Đặc tả trigger và transaction nghiệp vụ | C32: TV3 | D32: =IFERROR(INDEX('Thành viên'!$B$6:$B$10,MATCH($C32,'Thành viên'!$A$6:$A$10,0))&"","")
A33: 4.8 | B33: Truy vấn hiển thị theo yêu cầu đề | C33: TV5 | D33: =IFERROR(INDEX('Thành viên'!$B$6:$B$10,MATCH($C33,'Thành viên'!$A$6:$A$10,0))&"","")
A34: 4.9 | B34: Tối ưu truy vấn bằng chỉ mục | C34: TV5 | D34: =IFERROR(INDEX('Thành viên'!$B$6:$B$10,MATCH($C34,'Thành viên'!$A$6:$A$10,0))&"","")
A35: 4.10 | B35: An toàn bảo mật | C35: TV5 | D35: =IFERROR(INDEX('Thành viên'!$B$6:$B$10,MATCH($C35,'Thành viên'!$A$6:$A$10,0))&"","")
A36: 4.11 | B36: Kiểm thử ràng buộc, trigger và transaction | C36: TV5 | D36: =IFERROR(INDEX('Thành viên'!$B$6:$B$10,MATCH($C36,'Thành viên'!$A$6:$A$10,0))&"","")
A37: 4.12 | B37: Bảng mã lỗi nghiệp vụ | C37: TV5 | D37: =IFERROR(INDEX('Thành viên'!$B$6:$B$10,MATCH($C37,'Thành viên'!$A$6:$A$10,0))&"","")
A38: 4.13 | B38: Giao diện ứng dụng | C38: TV5 | D38: =IFERROR(INDEX('Thành viên'!$B$6:$B$10,MATCH($C38,'Thành viên'!$A$6:$A$10,0))&"","")
A39: CHƯƠNG 5. PHÂN TÍCH VÀ THIẾT KẾ CƠ SỞ DỮ LIỆU PHÂN TÁN
A40: 5.1 | B40: Bối cảnh và kiến trúc | C40: TV4 | D40: =IFERROR(INDEX('Thành viên'!$B$6:$B$10,MATCH($C40,'Thành viên'!$A$6:$A$10,0))&"","")
A41: 5.2 | B41: Số liệu giả định dùng cho thiết kế | C41: TV4 | D41: =IFERROR(INDEX('Thành viên'!$B$6:$B$10,MATCH($C41,'Thành viên'!$A$6:$A$10,0))&"","")
...

Sheet Kiểm thử SQL
A1: 52 ca kiểm thử trong 08_test.sql
A2: Cột TV là chủ của đối tượng được kiểm thử, người giải thích ca đó khi bị hỏi. TV5 viết khung và chạy cả bộ (kết quả 52/52 đạt).
A4: Mã ca | B4: Mô tả | C4: TV | D4: Họ tên
A5: TX1-a | B5: Mượn 11 cuốn trong 1 phiếu bị chặn | C5: TV3 | D5: =IFERROR(INDEX('Thành viên'!$B$6:$B$10,MATCH($C5,'Thành viên'!$A$6:$A$10,0))&"","")
A6: TX1-b | B6: Sau khi bị chặn không có phiếu mượn nào được tạo (ROLLBACK) | C6: TV3 | D6: =IFERROR(INDEX('Thành viên'!$B$6:$B$10,MATCH($C6,'Thành viên'!$A$6:$A$10,0))&"","")
A7: TX1-c | B7: Mượn đúng 10 cuốn hợp lệ | C7: TV3 | D7: =IFERROR(INDEX('Thành viên'!$B$6:$B$10,MATCH($C7,'Thành viên'!$A$6:$A$10,0))&"","")
A8: TRG1 | B8: Chèn trực tiếp cuốn thứ 11 vào phiếu đã có 10 cuốn | C8: TV3 | D8: =IFERROR(INDEX('Thành viên'!$B$6:$B$10,MATCH($C8,'Thành viên'!$A$6:$A$10,0))&"","")
A9: TRG4-a | B9: Số lượng trên giá giảm đúng bằng số cuốn của giá đó vừa được mượn | C9: TV1 | D9: =IFERROR(INDEX('Thành viên'!$B$6:$B$10,MATCH($C9,'Thành viên'!$A$6:$A$10,0))&"","")
A10: TRG5 | B10: Tuổi thọ cuốn sách giảm 1 tháng sau khi mượn | C10: TV1 | D10: =IFERROR(INDEX('Thành viên'!$B$6:$B$10,MATCH($C10,'Thành viên'!$A$6:$A$10,0))&"","")
A11: TX1-d | B11: Hạn trả = ngày mượn + số ngày mượn của thể loại/đầu sách | C11: TV3 | D11: =IFERROR(INDEX('Thành viên'!$B$6:$B$10,MATCH($C11,'Thành viên'!$A$6:$A$10,0))&"","")
A12: TRG2-a | B12: Mượn cuốn đang được người khác mượn | C12: TV3 | D12: =IFERROR(INDEX('Thành viên'!$B$6:$B$10,MATCH($C12,'Thành viên'!$A$6:$A$10,0))&"","")
A13: TRG2-b | B13: Độc giả DG0001 đang giữ 50 cuốn mượn thêm 1 cuốn | C13: TV3 | D13: =IFERROR(INDEX('Thành viên'!$B$6:$B$10,MATCH($C13,'Thành viên'!$A$6:$A$10,0))&"","")
A14: TX1-e | B14: Danh sách mượn có mã cuốn bị lặp | C14: TV3 | D14: =IFERROR(INDEX('Thành viên'!$B$6:$B$10,MATCH($C14,'Thành viên'!$A$6:$A$10,0))&"","")
A15: TX2-a | B15: Trả cuốn mà độc giả không mượn | C15: TV3 | D15: =IFERROR(INDEX('Thành viên'!$B$6:$B$10,MATCH($C15,'Thành viên'!$A$6:$A$10,0))&"","")
A16: TX2-b | B16: Trả muộn 5 ngày 2 cuốn (1 phiếu trả, nhiều cuốn) | C16: TV3 | D16: =IFERROR(INDEX('Thành viên'!$B$6:$B$10,MATCH($C16,'Thành viên'!$A$6:$A$10,0))&"","")
... A56: TV-4 | B56: Không có 2 lượt thuê đã duyệt trùng giờ cùng phòng | C56: TV5 | D56: =IFERROR(INDEX('Thành viên'!$B$6:$B$10,MATCH($C56,'Thành viên'!$A$6:$A$10,0))&"","")

Sheet Giao diện
A1: 23 thao tác giao diện được kiểm thử tự động
A2: Theo chup_man_hinh.py và ket_qua_giao_dien.json (23/23 đạt). Thao tác kết quả 'Bị chặn' là ca cố tình vi phạm luật để CSDL báo lỗi.
A4: STT | B4: Trang | C4: Thao tác | D4: Mong đợi | E4: Thông báo nhận được | F4: TV | G4: Họ tên
A5: 1 | B5: Mượn sách | C5: Lập phiếu mượn | D5: Thành công | E5: Đã lập phiếu mượn số: 832 | F5: TV3 | G5: =IFERROR(INDEX('Thành viên'!$B$6:$B$10,MATCH($F5,'Thành viên'!$A$6:$A$10,0))&"","")
A6: 2 | B6: Mượn sách | C6: Lập phiếu mượn | D6: Bị chặn | E6: E101: Mỗi lần mượn tối đa 10 cuốn sách | F6: TV3 | G6: =IFERROR(INDEX('Thành viên'!$B$6:$B$10,MATCH($F6,'Thành viên'!$A$6:$A$10,0))&"","")
A7: 3 | B7: Trả sách & phạt | C7: Lập phiếu trả | D7: Thành công | E7: Đã trả: phiếu 1569, tiền phạt 3.470.000 đ | F7: TV3 | G7: =IFERROR(INDEX('Thành viên'!$B$6:$B$10,MATCH($F7,'Thành viên'!$A$6:$A$10,0))&"","")
A8: 4 | B8: Trả sách & phạt | C8: Thanh toán toàn bộ phạt | D8: Thành công | E8: Đã thu: 3.470.000 đ | F8: TV3 | G8: =IFERROR(INDEX('Thành viên'!$B$6:$B$10,MATCH($F8,'Thành viên'!$A$6:$A$10,0))&"","")
A9: 5 | B9: Phòng đọc | C9: Thêm phòng | D9: Thành công | E9: Đã thêm phòng CN01-N6 | F9: TV4 | G9: =IFERROR(INDEX('Thành viên'!$B$6:$B$10,MATCH($F9,'Thành viên'!$A$6:$A$10,0))&"","")
A10: 6 | B10: Phòng đọc | C10: Sửa tên / sức chứa | D10: Thành công | E10: Đã sửa phòng CN01-N6 | F10: TV4 | G10: =IFERROR(INDEX('Thành viên'!$B$6:$B$10,MATCH($F10,'Thành viên'!$A$6:$A$10,0))&"","")
A11: 7 | B11: Phòng đọc | C11: Xóa phòng | D11: Thành công | E11: Đã xóa phòng CN01-N6 | F11: TV4 | G11: =IFERROR(INDEX('Thành viên'!$B$6:$B$10,MATCH($F11,'Thành viên'!$A$6:$A$10,0))&"","")
A12: 8 | B12: Độc giả | C12: Đăng ký | D12: Thành công | E12: Đã đăng ký: mã DG0201, thẻ THE0201 | F12: TV2 | G12: =IFERROR(INDEX('Thành viên'!$B$6:$B$10,MATCH($F12,'Thành viên'!$A$6:$A$10,0))&"","")
A13: 9 | B13: Độc giả | C13: Lưu sửa | D13: Thành công | E13: Đã sửa DG0201 | F13: TV2 | G13: =IFERROR(INDEX('Thành viên'!$B$6:$B$10,MATCH($F13,'Thành viên'!$A$6:$A$10,0))&"","")
A14: 10 | B14: Độc giả | C14: Gia hạn thẻ 1 năm | D14: Thành công | E14: Đã gia hạn thẻ DG0201 | F14: TV2 | G14: =IFERROR(INDEX('Thành viên'!$B$6:$B$10,MATCH($F14,'Thành viên'!$A$6:$A$10,0))&"","")
A15: 11 | B15: Độc giả | C15: Xóa độc giả | D15: Thành công | E15: Đã xóa DG0201 | F15: TV2 | G15: =IFERROR(INDEX('Thành viên'!$B$6:$B$10,MATCH($F15,'Thành viên'!$A$6:$A$10,0))&"","")
A16: 12 | B16: Độc giả | C16: Xóa độc giả | D16: Bị chặn | E16: E404: Độc giả còn giữ sách, không xóa được | F16: TV2 | G16: =IFERROR(INDEX('Thành viên'!$B$6:$B$10,MATCH($F16,'Thành viên'!$A$6:$A$10,0))&"","")
... A27: 23 | B27: Thủ thư & chi nhánh | C27: Xóa thủ thư | D27: Bị chặn | E27: E403: Thủ thư đang là trưởng chi nhánh, đổi trưởng trước khi xóa | F27: TV2 | G27: =IFERROR(INDEX('Thành viên'!$B$6:$B$10,MATCH($F27,'Thành viên'!$A$6:$A$10,0))&"","")

Sheet Lịch thuyết trình
A1: Thứ tự trình bày và demo
A2: Thời lượng (ô vàng) là giả định 6 phút mỗi người, sửa theo thời gian giảng viên cho. Phần demo nên chiếm quá nửa thời lượng mỗi người. Dựng lại CSDL sạch trước khi demo.
A4: Lượt | B4: TV | C4: Họ tên | D4: Nội dung trình bày | E4: Demo | F4: Phút
A5: 1 | B5: TV1 | C5: =IFERROR(INDEX('Thành viên'!$B$6:$B$10,MATCH($B5,'Thành viên'!$A$6:$A$10,0))&"","") | D5: Bài toán, yêu cầu, ERD tổng, mảng sách và kho | E5: Sách & kho, tuổi thọ | F5: 6
A6: 2 | B6: TV2 | C6: =IFERROR(INDEX('Thành viên'!$B$6:$B$10,MATCH($B6,'Thành viên'!$A$6:$A$10,0))&"","") | D6: Ánh xạ sang quan hệ, chuẩn hóa BCNF, mảng con người, dữ liệu 3 tháng | E6: Đăng ký độc giả, chặn xóa thủ thư là trưởng chi nhánh (E403) | F6: 6
A7: 3 | B7: TV3 | C7: =IFERROR(INDEX('Thành viên'!$B$6:$B$10,MATCH($B7,'Thành viên'!$A$6:$A$10,0))&"","") | D7: Mượn, trả, phạt; trigger và transaction | E7: Mượn quá 10 cuốn (E101), mượn thành công, trả có phạt, thanh toán | F7: 6
A8: 4 | B8: TV4 | C8: =IFERROR(INDEX('Thành viên'!$B$6:$B$10,MATCH($B8,'Thành viên'!$A$6:$A$10,0))&"","") | D8: Phòng đọc; thiết kế CSDL phân tán | E8: Báo giá và thuê phòng, trùng giờ (E201); chạy 36 ca phân tán | F8: 6
A9: 5 | B9: TV5 | C9: =IFERROR(INDEX('Thành viên'!$B$6:$B$10,MATCH($B9,'Thành viên'!$A$6:$A$10,0))&"","") | D9: Truy vấn, chỉ mục, bảo mật, kiểm thử | E9: Báo cáo, chạy 52 ca kiểm thử, quyền của tt_cn01 | F9: 6
A10: 6 | B10: TV1 | C10: =IFERROR(INDEX('Thành viên'!$B$6:$B$10,MATCH($B10,'Thành viên'!$A$6:$A$10,0))&"","") | D10: Kết luận, hạn chế, hướng phát triển | E10: — | F10: 2
E11: Tổng thời lượng | F11: =SUM(F5:F10) -> 32
